Workbook
Name AA: #REF!
Name GG: #REF!
Name ID: #REF!
Name ID: #REF!
Name ID: #REF!
Name ID: [1]입출고!#REF!
Name YY: #REF!
Name 계산서: #REF!
Name 계산서: #REF!
Name 계산서: #REF!
Name 계산서: [1]입출고!#REF!
Name 계약금: #REF!
Name 계약금: #REF!
Name 계약금: #REF!
Name 계약금: [1]입출고!#REF!
Name 광택: #REF!
Name 광택: #REF!
Name 광택: #REF!
Name 광택: [1]입출고!#REF!
Name 구분입력: [2]수출현황_종합!$G$2
Name 구분입력2: [2]수출현황_종합!$G$3
Name 기준날짜: [2]수출현황_종합!$J$3
Name 기준월: [2]수출현황_종합!$C$3
Name 기타: #REF!
Name 기타: #REF!
Name 기타: #REF!
Name 기타: [1]입출고!#REF!
Name ㄴㅇㄹ: #REF!
Name 년도: [2]수출현황_종합!$B$3
Name 등급: #REF!
Name 등급: #REF!
Name 등급: #REF!
Name 등급: [1]입출고!#REF!
Name 말소날짜: #REF!
Name 말소날짜: #REF!
Name 말소날짜: #REF!
Name 말소날짜: [1]입출고!#REF!
Name 말소증2: [1]입출고!#REF!
Name 매입가: #REF!
Name 매입가: #REF!
Name 매입가: #REF!
Name 매입가: [1]입출고!#REF!
Name 매입날짜: #REF!
Name 매입날짜: #REF!
Name 매입날짜: #REF!
Name 매입날짜: [1]입출고!#REF!
Name 메다: #REF!
Name 메다: #REF!
Name 메다: #REF!
Name 메다: [1]입출고!#REF!
Name 미수: #REF!
Name 미수: #REF!
Name 미수: #REF!
Name 미수: [1]입출고!#REF!
Name 바이어연락처: #REF!
Name 바이어연락처: #REF!
Name 바이어연락처: #REF!
Name 바이어연락처: [1]입출고!#REF!
Name 변속기: #REF!
Name 변속기: #REF!

Sheet 달러 판매현황
A1: NO | B1: 구입일자 | C1: EVOQUE | D1: 30무0996 | E1: CHASSIS NUMBER | F1: 판매자 정보 | G1: 계약금 | H1: 바이어 회사명 | I1: 고객컨사이니 | J1: 고객 ID / 비즈니스 넘버 | K1: 전화번호 | L1: 나라 | M1: 구입금액 | N1: 매도비 | O1: 총 구입금액 | P1: 유로 | Q1: 상태 | R1: 판매보고 여부 | S1: 입금여부 | T1: 판매금액 | U1: 환율 1$ | V1: 운임 | W1: 커미션 | X1: 디스카운트 | Y1: 부가세 | Z1: 판매 총 합계 | AA1: 입금합계 | AB1: 미수금 | AC1: 메모 | AD1: 메모 | AE1: 입금날짜01 | AF1: 정산01 | AG1: 입금날짜02 | AH1: 정산02 | AI1: 입금날짜03 | AJ1: 정산03 | AK1: 적립금 사용 | AL1: 선수금 | AM1: 말소/면허 | AN1: 탁송 | AO1: 캐리어 | AP1: 쇼링 | AQ1: 기타 | AR1: 합계 | AS1: 정산판매금 원화 | AT1: 판매마진 | AU1: 부가세 마진 | AV1: 총 마진 | AW1: 지급액 | AX1: 서류공제 | AY1: 비용공제 | AZ1: 실지급액 | BA1: 돈받은거
A2: 1 | B2: 45970 | C2: A4 | D2: 22러6510 | E2: WAUZZZ8K0CA054269 | F2: 카팡 / 김동영 | H2: AUTO-ANDI | I2: Andi Cereku | J2: M34710201A | K2: 696688738 | L2: Albania | M2: 4300000 | N2: 0 | O2: =M2+N2 -> 4300000 | P2: USD | Q2: 출고 | R2: 완 | S2: 입금완료 | T2: 3030 | U2: 1443 | V2: 1670 | Z2: =SUM(T2,V2:Y2) -> 4700 | AA2: =SUM(AF2+AH2+AJ2+AK2-AL2) -> 0 | AB2: =SUM(AA2-Z2) -> -4700 | AM2: 35000 | AN2: 30000 | AR2: =SUM(AM2:AQ2) -> 65000 | AS2: =SUM(Z2-V2)*U2-AR2 -> 4307290 | AT2: =SUM(AS2-O2) -> 7290 | AU2: =SUM(M2*0.09) -> 387000 | AV2: =SUM(AT2:AU2)/2 -> 197145 | AW2: =AV2-(AV2*10%) -> 177430.5 | AX2: 50000 | AZ2: =SUM(AW2-AX2-AY2) -> 127430.5
A3: 2 | B3: 45970 | C3: A6 35 TDI | D3: 06어6962 | E3: WAUZZZ4G0JN115661 | F3: 하이앤드 / 김기헌 | H3: Faturat Net Sh.p.k | I3: Faturat Net Sh.p.k | J3: 811577636 | K3: +38349930085, +38344371274 | L3: Kosovo | M3: 17960000 | N3: 440000 | O3: =M3+N3 -> 18400000 | P3: USD | Q3: 출고 | R3: 완 | S3: 입금완료 | T3: 12430 | U3: 1443 | V3: 1670 | Z3: =SUM(T3,V3:Y3) -> 14100 | AA3: =SUM(AF3+AH3+AJ3+AK3-AL3) -> 0 | AB3: =SUM(AA3-Z3) -> -14100 | AM3: 35000 | AN3: 30000 | AR3: =SUM(AM3:AQ3) -> 65000 | AS3: =SUM(Z3-V3)*U3-AR3 -> 17871490 | AT3: =SUM(AS3-O3) -> -528510 | AU3: =SUM(M3*0.09) -> 1616400 | AV3: =SUM(AT3:AU3)/2 -> 543945 | AW3: =AV3-(AV3*10%) -> 489550.5 | AX3: 50000 | AZ3: =SUM(AW3-AX3-AY3) -> 439550.5
A4: 3 | B4: 45978 | C4: TUCSON | D4: 154라1419 | E4: KMHJ2814BGU023329 | F4: 이동근 ( 단독명의 ) | H4: AUTO-ANDI | I4: Andi Cereku | J4: M34710201A | K4: 696688738 | L4: Albania | M4: 8600000 | N4: 0 | O4: =M4+N4 -> 8600000 | P4: USD | Q4: 출고 | R4: 완 | S4: 입금완료 | T4: 6080 | U4: 1451 | V4: 1770 | Z4: =SUM(T4,V4:Y4) -> 7850 | AA4: =SUM(AF4+AH4+AJ4+AK4-AL4) -> 0 | AB4: =SUM(AA4-Z4) -> -7850 | AM4: 35000 | AN4: 30000 | AR4: =SUM(AM4:AQ4) -> 65000 | AS4: =SUM(Z4-V4)*U4-AR4 -> 8757080 | AT4: =SUM(AS4-O4) -> 157080 | AU4: =SUM(M4*0.09) -> 774000 | AV4: =SUM(AT4:AU4)/2 -> 465540 | AW4: =AV4-(AV4*10%) -> 418986 | AX4: 50000 | AZ4: =SUM(AW4-AX4-AY4) -> 368986
A5: 4 | B5: 45978 | C5: A6 3.0TDI | D5: 229누1701 | E5: WAUZZZ4G8EN159977 | F5: 열린모터스 / 장재완 | H5: AUTO-ANDI | I5: Andi Cereku | J5: M34710201A | K5: 696688738 | L5: Albania | M5: 4200000 | N5: 440000 | O5: =M5+N5 -> 4640000 | P5: USD | Q5: 출고 | R5: 완 | S5: 입금완료 | T5: 3280 | U5: 1455 | V5: 1670 | Z5: =SUM(T5,V5:Y5) -> 4950 | AA5: =SUM(AF5+AH5+AJ5+AK5-AL5) -> 0 | AB5: =SUM(AA5-Z5) -> -4950 | AM5: 35000 | AN5: 30000 | AR5: =SUM(AM5:AQ5) -> 65000 | AS5: =SUM(Z5-V5)*U5-AR5 -> 4707400 | AT5: =SUM(AS5-O5) -> 67400 | AU5: =SUM(M5*0.09) -> 378000 | AV5: =SUM(AT5:AU5)/2 -> 222700 | AW5: =AV5-(AV5*10%) -> 200430 | AX5: 50000 | AZ5: =SUM(AW5-AX5-AY5) -> 150430
A6: 5 | B6: 45978 | C6: GOLF | D6: 154두4776 | E6: WVWZZZ1KZDW080415 | F6: 레인보우 / 김태균 | H6: AUTO-ANDI | I6: Andi Cereku | J6: M34710201A | K6: 696688738 | L6: Albania | M6: 4300000 | N6: 440000 | O6: =M6+N6 -> 4740000 | P6: USD | Q6: 출고 | R6: 완 | S6: 입금완료 | T6: 3180 | U6: 1455 | V6: 1670 | Z6: =SUM(T6,V6:Y6) -> 4850 | AA6: =SUM(AF6+AH6+AJ6+AK6-AL6) -> 0 | AB6: =SUM(AA6-Z6) -> -4850 | AM6: 35000 | AN6: 30000 | AR6: =SUM(AM6:AQ6) -> 65000 | AS6: =SUM(Z6-V6)*U6-AR6 -> 4561900 | AT6: =SUM(AS6-O6) -> -178100 | AU6: =SUM(M6*0.09) -> 387000 | AV6: =SUM(AT6:AU6)/2 -> 104450 | AW6: =AV6-(AV6*10%) -> 94005 | AX6: 50000 | AZ6: =SUM(AW6-AX6-AY6) -> 44005
A7: 6 | B7: 45979 | C7: A8 4.2 FSI quattro | D7: 64나2492 | E7: WAUZZZ4H4B002161 | F7: 왕카 / 이민우 | H7: Myzejen Zajaku | L7: Albania (신규) | M7: 7100000 | N7: 0 | O7: =M7+N7 -> 7100000 | Q7: 출고 | R7: 완 | S7: 입금완료 | T7: 5382 | U7: 1457 | Z7: =SUM(T7,V7:Y7) -> 5382 | AA7: =SUM(AF7+AH7+AJ7+AK7-AL7) -> 0 | AB7: =SUM(AA7-Z7) -> -5382 | AM7: 35000 | AN7: 30000 | AR7: =SUM(AM7:AQ7) -> 65000 | AS7: =SUM(Z7-V7)*U7-AR7 -> 7776574 | AT7: =SUM(AS7-O7) -> 676574 | AU7: =SUM(M7*0.09) -> 639000 | AV7: =SUM(AT7:AU7)/2 -> 657787 | AW7: =AV7-(AV7*10%) -> 592008.3 | AX7: 50000 | AZ7: =SUM(AW7-AX7-AY7) -> 542008.3
A8: 7 | B8: 45981 | C8: 730D xDrive M Sport Package | D8: 335루1767 | E8: WBA7S4107LCE80376 | F8: 오토웨이브 김경호 | H8: Faturat Net Sh.p.k | I8: Faturat Net Sh.p.k | J8: 811577636 | K8: +38349930085, +38344371274 | L8: Kosovo | M8: 53600000 | N8: 0 | O8: =M8+N8 -> 53600000 | P8: USD | Q8: 출고 | R8: 완 | S8: 입금완료 | T8: 35330 | U8: 1453 | Z8: =SUM(T8,V8:Y8) -> 35330 | AA8: =SUM(AF8+AH8+AJ8+AK8-AL8) -> 0 | AB8: =SUM(AA8-Z8) -> -35330 | AM8: 35000 | AN8: 30000 | AR8: =SUM(AM8:AQ8) -> 65000 | AS8: =SUM(Z8-V8)*U8-AR8 -> 51269490 | AT8: =SUM(AS8-O8) -> -2330510 | AU8: =SUM(M8*0.09) -> 4824000 | AV8: =SUM(AT8:AU8)/2 -> 1246745 | AW8: =AV8-(AV8*10%) -> 1122070.5 | AX8: 50000 | AZ8: =SUM(AW8-AX8-AY8) -> 1072070.5
A9: 8 | B9: 45985 | C9: TIGUAN | D9: 35어2331 | E9: WVGZZZ5NZCW067974 | F9: 레인보우 / 박주용 | H9: AUTO-ANDI | I9: Andi Cereku | J9: M34710201A | K9: 696688738 | L9: Albania | M9: 5800000 | N9: 440000 | O9: =M9+N9 -> 6240000 | P9: USD | Q9: 출고 | R9: 완 | S9: 입금완료 | T9: 4180 | U9: 1455 | V9: 1770 | Z9: =SUM(T9,V9:Y9) -> 5950 | AA9: =SUM(AF9+AH9+AJ9+AK9-AL9) -> 0 | AB9: =SUM(AA9-Z9) -> -5950 | AM9: 35000 | AN9: 30000 | AR9: =SUM(AM9:AQ9) -> 65000 | AS9: =SUM(Z9-V9)*U9-AR9 -> 6016900 | AT9: =SUM(AS9-O9) -> -223100 | AU9: =SUM(M9*0.09) -> 522000 | AV9: =SUM(AT9:AU9)/2 -> 149450 | AW9: =AV9-(AV9*10%) -> 134505 | AX9: 50000 | AZ9: =SUM(AW9-AX9-AY9) -> 84505
A10: 9 | B10: 45986 | C10: A4 2.0 TDI | D10: 23누7083 | E10: WAUZZZ8K8EA084462 | F10: 카카오토샵 / 김대환 | H10: AUTO-ANDI | I10: Andi Cereku | J10: M34710201A | K10: 696688738 | L10: Albania | M10: 6840000 | N10: 0 | O10: =M10+N10 -> 6840000 | P10: USD | Q10: 출고 | R10: 완 | S10: 입금완료 | T10: 4680 | U10: 1455 | V10: 1670 | Z10: =SUM(T10,V10:Y10) -> 6350 | AA10: =SUM(AF10+AH10+AJ10+AK10-AL10) -> 0 | AB10: =SUM(AA10-Z10) -> -6350 | AM10: 35000 | AN10: 30000 | AR10: =SUM(AM10:AQ10) -> 65000 | AS10: =SUM(Z10-V10)*U10-AR10 -> 6744400 | AT10: =SUM(AS10-O10) -> -95600 | AU10: =SUM(M10*0.09) -> 615600 | AV10: =SUM(AT10:AU10)/2 -> 260000 | AW10: =AV10-(AV10*10%) -> 234000 | AX10: 50000 | AZ10: =SUM(AW10-AX10-AY10) -> 184000 | BA10: 0
A11: 10 | B11: 45986 | C11: TUCSON | D11: 60너2048 | E11: KMHJU81VBAU079072 | F11: 서청주자동차 / 이태곤 | H11: AUTO-ANDI | I11: Andi Cereku | J11: M34710201A | K11: 696688738 | L11: Albania | M11: 4850000 | N11: 0 | O11: =M11+N11 -> 4850000 | P11: USD | Q11: 출고 | R11: 완 | S11: 입금완료 | T11: 3430 | U11: 1455 | V11: 1770 | Z11: =SUM(T11,V11:Y11) -> 5200 | AA11: =SUM(AF11+AH11+AJ11+AK11-AL11) -> 0 | AB11: =SUM(AA11-Z11) -> -5200 | AM11: 35000 | AN11: 30000 | AR11: =SUM(AM11:AQ11) -> 65000 | AS11: =SUM(Z11-V11)*U11-AR11 -> 4925650 | AT11: =SUM(AS11-O11) -> 75650 | AU11: =SUM(M11*0.09) -> 436500 | AV11: =SUM(AT11:AU11)/2 -> 256075 | AW11: =AV11-(AV11*10%) -> 230467.5 | AX11: 50000 | AZ11: =SUM(AW11-AX11-AY11) -> 180467.5 | BA11: 0
A12: 11 | B12: 45989 | C12: TIGUAN | D12: 17두 7937 | E12: WVGZZZ5NZJW932354 | F12: 리본카 최은선 | H12: Faturat Net Sh.p.k | I12: Faturat Net Sh.p.k | J12: 811577636 | K12: +38349930085, +38344371274 | L12: Kosovo | M12: 21140000 | N12: 0 | O12: =M12+N12 -> 21140000 | P12: USD | Q12: 출고 | R12: 완 | S12: 입금완료 | T12: 13880 | U12: 1448 | V12: 1770 | Z12: =SUM(T12,V12:Y12) -> 15650 | AA12: =SUM(AF12+AH12+AJ12+AK12-AL12) -> 0 | AB12: =SUM(AA12-Z12) -> -15650 | AM12: 35000 | AN12: 30000 | AR12: =SUM(AM12:AQ12) -> 65000 | AS12: =SUM(Z12-V12)*U12-AR12 -> 20033240 | AT12: =SUM(AS12-O12) -> -1106760 | AU12: =SUM(M12*0.09) -> 1902600 | AV12: =SUM(AT12:AU12)/2 -> 397920 | AW12: =AV12-(AV12*10%) -> 358128 | AX12: 50000 | AZ12: =SUM(AW12-AX12-AY12) -> 308128 | BA12: 0
A13: 12 | B13: 46358 | C13: TIGUAN | D13: 252너3597 | E13: WVGZZZ5NZJW951937 | F13: 우리모터스 지경철 | H13: Faturat Net Sh.p.k | I13: Faturat Net Sh.p.k | J13: 811577636 | K13: +38349930085, +38344371274 | L13: Kosovo | M13: 18000000 | N13: 300000 | O13: =M13+N13 -> 18300000 | P13: USD | Q13: 출고 | R13: 완 | S13: 입금완료 | T13: 12075 | U13: 1456 | V13: 1770 | Z13: =SUM(T13,V13:Y13) -> 13845 | AA13: =SUM(AF13+AH13+AJ13+AK13-AL13) -> 0 | AB13: =SUM(AA13-Z13) -> -13845 | AM13: 35000 | AN13: 30000 | AR13: =SUM(AM13:AQ13) -> 65000 | AS13: =SUM(Z13-V13)*U13-AR13 -> 17516200 | AT13: =SUM(AS13-O13) -> -783800 | AU13: =SUM(M13*0.09) -> 1620000 | AV13: =SUM(AT13:AU13)/2 -> 418100 | AW13: =AV13-(AV13*10%) -> 376290 | AX13: 50000 | AZ13: =SUM(AW13-AX13-AY13) -> 326290
A14: 13 | B14: 45999 | C14: A6 | D14: 28러9364 | E14: WAUZZZ4G1CN123674 | F14: 다정자동차 / 이경범 | H14: AUTO-ANDI | I14: Andi Cereku | J14: M34710201A | K14: 696688738 | L14: Albania | M14: 5600000 | N14: 0 | O14: =M14+N14 -> 5600000 | P14: USD | Q14: 출고 | R14: 완 | S14: 입금완료 | T14: 3930 | U14: 1461 | V14: 1670 | Z14: =SUM(T14,V14:Y14) -> 5600 | AA14: =SUM(AF14+AH14+AJ14+AK14-AL14) -> 0 | AB14: =SUM(AA14-Z14) -> -5600 | AM14: 35000 | AN14: 30000 | AR14: =SUM(AM14:AQ14) -> 65000 | AS14: =SUM(Z14-V14)*U14-AR14 -> 5676730 | AT14: =SUM(AS14-O14) -> 76730 | AU14: =SUM(M14*0.09) -> 504000 | AV14: =SUM(AT14:AU14)/2 -> 290365 | AW14: =AV14-(AV14*10%) -> 261328.5 | AX14: 50000 | AZ14: =SUM(AW14-AX14-AY14) -> 211328.5
A15: 14 | B15: 46002 | C15: TUCSON | D15: 11고5126 | E15: KMHJ381ABGU010115 | F15: 대양모터스 / 김남길 | H15: AUTO-ANDI | I15: Andi Cereku | J15: M34710201A | K15: 696688738 | L15: Albania | M15: 8100000 | N15: 440000 | O15: =M15+N15 -> 8540000 | P15: USD | Q15: 출고 | R15: 완 | S15: 입금완료 | T15: 5630 | U15: 1453 | V15: 1770 | Z15: =SUM(T15,V15:Y15) -> 7400 | AA15: =SUM(AF15+AH15+AJ15+AK15-AL15) -> 0 | AB15: =SUM(AA15-Z15) -> -7400 | AM15: 35000 | AN15: 30000 | AR15: =SUM(AM15:AQ15) -> 65000 | AS15: =SUM(Z15-V15)*U15-AR15 -> 8115390 | AT15: =SUM(AS15-O15) -> -424610 | AU15: =SUM(M15*0.09) -> 729000 | AV15: =SUM(AT15:AU15)/2 -> 152195 | AW15: =AV15-(AV15*10%) -> 136975.5 | AX15: 50000 | AZ15: =SUM(AW15-AX15-AY15) -> 86975.5
A16: 15 | B16: 46002 | C16: Grand Cherokee | D16: 68우 8964 | E16: 1J8HR58N27C686873 | F16: 다정모터스 / 김효남 | H16: AUTO-ANDI | I16: Andi Cereku | J16: M34710201A | K16: 696688738 | L16: Albania | M16: 4900000 | N16: 0 | O16: =M16+N16 -> 4900000 | P16: USD | Q16: 출고 | R16: 완 | S16: 입금완료 | T16: 3430 | U16: 1453 | V16: 1870 | Z16: =SUM(T16,V16:Y16) -> 5300 | AA16: =SUM(AF16+AH16+AJ16+AK16-AL16) -> 0 | AB16: =SUM(AA16-Z16) -> -5300 | AM16: 35000 | AN16: 30000 | AR16: =SUM(AM16:AQ16) -> 65000 | AS16: =SUM(Z16-V16)*U16-AR16 -> 4918790 | AT16: =SUM(AS16-O16) -> 18790 | AU16: =SUM(M16*0.09) -> 441000 | AV16: =SUM(AT16:AU16)/2 -> 229895 | AW16: =AV16-(AV16*10%) -> 206905.5 | AX16: 50000 | AZ16: =SUM(AW16-AX16-AY16) -> 156905.5
A17: 16 | B17: 46005 | C17: PORTER | D17: 841더3420 | E17: KMFZCZ7KAEU969321 | F17: 드림카마켓 / 이승호 | H17: AUTO-ANDI | I17: Andi Cereku | J17: M34710201A | K17: 696688738 | L17: Albania | M17: 5400000 | N17: 0 | O17: =M17+N17 -> 5400000 | P17: USD | Q17: 출고 | R17: 완 | S17: 입금완료 | T17: 3730 | U17: 1463 | V17: 1870 | Z17: =SUM(T17,V17:Y17) -> 5600 | AA17: =SUM(AF17+AH17+AJ17+AK17-AL17) -> 0 | AB17: =SUM(AA17-Z17) -> -5600 | AM17: 35000 | AN17: 30000 | AR17: =SUM(AM17:AQ17) -> 65000 | AS17: =SUM(Z17-V17)*U17-AR17 -> 5391990 | AT17: =SUM(AS17-O17) -> -8010 | AU17: =SUM(M17*0.09) -> 486000 | AV17: =SUM(AT17:AU17)/2 -> 238995 | AW17: =AV17-(AV17*10%) -> 215095.5 | AX17: 50000 | AZ17: =SUM(AW17-AX17-AY17) -> 165095.5
A18: 17 | B18: 46015 | C18: A6 3.0 TDI | D18: 39수0127 | E18: WAUZZZ4G3DN066671 | F18: 솔카 / 남승우 | H18: AUTO-ANDI | I18: Andi Cereku | J18: M34710201A | K18: 696688738 | L18: Albania | M18: 4800000 | N18: 440000 | O18: =M18+N18 -> 5240000 | P18: USD | Q18: 출고 | R18: 완 | S18: 입금완료 | T18: 4030 | U18: 1443 | V18: 1670 | Z18: =SUM(T18,V18:Y18) -> 5700 | AA18: =SUM(AF18+AH18+AJ18+AK18-AL18) -> 0 | AB18: =SUM(AA18-Z18) -> -5700 | AM18: 35000 | AN18: 30000 | AR18: =SUM(AM18:AQ18) -> 65000 | AS18: =SUM(Z18-V18)*U18-AR18 -> 5750290 | AT18: =SUM(AS18-O18) -> 510290 | AU18: =SUM(M18*0.09) -> 432000 | AV18: =SUM(AT18:AU18)/2 -> 471145 | AW18: =AV18-(AV18*10%) -> 424030.5 | AX18: 50000 | AZ18: =SUM(AW18-AX18-AY18) -> 374030.5
A19: 18 | B19: 46015 | C19: A6 3.0 TDI | D19: 56버0718 | E19: WAUZZZ4GXGN144836 | F19: 시대모터스 / 원종길 | H19: Faturat Net Sh.p.k | I19: Faturat Net Sh.p.k | J19: 811577636 | K19: +38349930085, +38344371274 | L19: Kosovo | M19: 14900000 | N19: 0 | O19: =M19+N19 -> 14900000 | P19: USD | Q19: 출고 | R19: 완 | S19: 입금완료 | T19: 9930 | U19: 1443 | V19: 1670 | Z19: =SUM(T19,V19:Y19) -> 11600 | AA19: =SUM(AF19+AH19+AJ19+AK19-AL19) -> 0 | AB19: =SUM(AA19-Z19) -> -11600 | AM19: 35000 | AN19: 30000 | AR19: =SUM(AM19:AQ19) -> 65000 | AS19: =SUM(Z19-V19)*U19-AR19 -> 14263990 | AT19: =SUM(AS19-O19) -> -636010 | AU19: =SUM(M19*0.09) -> 1341000 | AV19: =SUM(AT19:AU19)/2 -> 352495 | AW19: =AV19-(AV19*10%) -> 317245.5 | AX19: 50000 | AZ19: =SUM(AW19-AX19-AY19) -> 267245.5
A20: 19 | B20: 46015 | C20: TIGUAN | D20: 19거3283 | E20: WVGZZZ5NZCW593157 | F20: 수호모터스 / 배현진 | H20: AUTO-ANDI | I20: Andi Cereku | J20: M34710201A | K20: 696688738 | L20: Albania | M20: 6700000 | N20: 440000 | O20: =M20+N20 -> 7140000 | P20: USD | Q20: 출고 | R20: 완 | S20: 입금완료 | T20: 4830 | U20: 1443 | V20: 1770 | Z20: =SUM(T20,V20:Y20) -> 6600 | AA20: =SUM(AF20+AH20+AJ20+AK20-AL20) -> 0 | AB20: =SUM(AA20-Z20) -> -6600 | AM20: 35000 | AN20: 30000 | AR20: =SUM(AM20:AQ20) -> 65000 | AS20: =SUM(Z20-V20)*U20-AR20 -> 6904690 | AT20: =SUM(AS20-O20) -> -235310 | AU20: =SUM(M20*0.09) -> 603000 | AV20: =SUM(AT20:AU20)/2 -> 183845 | AW20: =AV20-(AV20*10%) -> 165460.5 | AX20: 50000 | AZ20: =SUM(AW20-AX20-AY20) -> 115460.5
A21: 20 | B21: 46015 | C21: TIGUAN | D21: 15노9510 | E21: WVGZZZ5NZGW534985 | F21: 오토웨이브 / 이문주 | H21: AUTO-ANDI | I21: Andi Cereku | J21: M34710201A | K21: 696688738 | L21: Albania | M21: 5400000 | N21: 0 | O21: =M21+N21 -> 5400000 | P21: USD | Q21: 출고 | R21: 완 | S21: 입금완료 | T21: 3730 | U21: 1443 | V21: 1770 | Z21: =SUM(T21,V21:Y21) -> 5500 | AA21: =SUM(AF21+AH21+AJ21+AK21-AL21) -> 0 | AB21: =SUM(AA21-Z21) -> -5500 | AM21: 35000 | AN21: 30000 | AR21: =SUM(AM21:AQ21) -> 65000 | AS21: =SUM(Z21-V21)*U21-AR21 -> 5317390 | AT21: =SUM(AS21-O21) -> -82610 | AU21: =SUM(M21*0.09) -> 486000 | AV21: =SUM(AT21:AU21)/2 -> 201695 | AW21: =AV21-(AV21*10%) -> 181525.5 | AX21: 50000
A22: 21 | B22: 46024 | C22: 320D GT | D22: 54라5106 | E22: WBA8T5103H816870 | F22: 태양모터스 / 이은선 | H22: Faturat Net Sh.p.k | I22: Faturat Net Sh.p.k | J22: 811577636 | K22: +38349930085, +38344371274 | L22: Kosovo | M22: 16400000 | N22: 440000 | O22: =M22+N22 -> 16840000 | P22: USD | Q22: 출고 | R22: 완 | S22: 입금완료 | T22: 11330 | U22: 1430 | V22: 1670 | Z22: =SUM(T22,V22:Y22) -> 13000 | AA22: =SUM(AF22+AH22+AJ22+AK22-AL22) -> 0 | AB22: =SUM(AA22-Z22) -> -13000 | AM22: 35000 | AN22: 30000 | AR22: =SUM(AM22:AQ22) -> 65000 | AS22: =SUM(Z22-V22)*U22-AR22 -> 16136900 | AT22: =SUM(AS22-O22) -> -703100 | AU22: =SUM(M22*0.09) -> 1476000 | AV22: =SUM(AT22:AU22)/2 -> 386450 | AW22: =AV22-(AV22*10%) -> 347805 | AX22: 50000 | AZ22: =SUM(AW22-AX22-AY22) -> 297805
A23: 22 | B23: 46024 | C23: TIGUAN | D23: 57어2189 | E23: WVGZZZ5NZEW568536 | F23: 제이모션 / 안태건 | H23: AUTO-ANDI | I23: Andi Cereku | J23: M34710201A | K23: 696688738 | L23: Albania | M23: 7600000 | N23: 0 | O23: =M23+N23 -> 7600000 | P23: USD | Q23: 출고 | R23: 완 | S23: 입금완료 | T23: 5230 | U23: 1426 | V23: 1770 | Z23: =SUM(T23,V23:Y23) -> 7000 | AA23: =SUM(AF23+AH23+AJ23+AK23-AL23) -> 0 | AB23: =SUM(AA23-Z23) -> -7000 | AM23: 35000 | AN23: 30000 | AR23: =SUM(AM23:AQ23) -> 65000 | AS23: =SUM(Z23-V23)*U23-AR23 -> 7392980 | AT23: =SUM(AS23-O23) -> -207020 | AU23: =SUM(M23*0.09) -> 684000 | AV23: =SUM(AT23:AU23)/2 -> 238490 | AW23: =AV23-(AV23*10%) -> 214641 | AX23: 50000 | AZ23: =SUM(AW23-AX23-AY23) -> 164641
A24: 23 | B24: 46024 | C24: TIGUAN | D24: 35버1628 | E24: WVGZZZ5NZBW045756 | F24: 이삼두 | H24: AUTO-ANDI | I24: Andi Cereku | J24: M34710201A | K24: 696688738 | L24: Albania | M24: 4000000 | N24: 0 | O24: =M24+N24 -> 4000000 | P24: USD | Q24: 출고 | R24: 완 | S24: 입금완료 | T24: 2930 | U24: 1430 | V24: 1770 | Z24: =SUM(T24,V24:Y24) -> 4700 | AA24: =SUM(AF24+AH24+AJ24+AK24-AL24) -> 0 | AB24: =SUM(AA24-Z24) -> -4700 | AD24: 개인 매입 건 | AM24: 35000 | AN24: 30000 | AR24: =SUM(AM24:AQ24) -> 65000 | AS24: =SUM(Z24-V24)*U24-AR24 -> 4124900 | AT24: =SUM(AS24-O24) -> 124900 | AU24: =SUM(M24*0.09) -> 360000 | AV24: =SUM(AT24:AU24)/2 -> 242450 | AW24: =AV24-(AV24*10%) -> 218205 | AX24: 50000 | AZ24: =SUM(AW24-AX24-AY24) -> 168205
A25: 24 | B25: 46027 | C25: TIGUAN | D25: 23두3351 | E25: WVGZZZ5NZDW604961 | F25: 유레카 / 박경철 | H25: AUTO-ANDI | I25: Andi Cereku | J25: M34710201A | K25: 696688738 | L25: Albania | M25: 6200000 | N25: 440000 | O25: =M25+N25 -> 6640000 | P25: USD | Q25: 출고 | R25: 완 | S25: 입금완료 | T25: 4880 | U25: 1435 | V25: 1770 | Z25: =SUM(T25,V25:Y25) -> 6650 | AA25: =SUM(AF25+AH25+AJ25+AK25-AL25) -> 0 | AB25: =SUM(AA25-Z25) -> -6650 | AM25: 35000 | AN25: 30000 | AR25: =SUM(AM25:AQ25) -> 65000 | AS25: =SUM(Z25-V25)*U25-AR25 -> 6937800 | AT25: =SUM(AS25-O25) -> 297800 | AU25: =SUM(M25*0.09) -> 558000 | AV25: =SUM(AT25:AU25)/2 -> 427900 | AW25: =AV25-(AV25*10%) -> 385110 | AX25: 50000 | AZ25: =SUM(AW25-AX25-AY25) -> 335110
A26: 25 | B26: 46028 | C26: Q5 | D26: 63무0374 | E26: WAUZZZ8R5F114452 | F26: 다정모터스 / 김다정 | H26: AUTO-ANDI | I26: Andi Cereku | J26: M34710201A | K26: 696688738 | L26: Albania | M26: 9500000 | N26: 0 | O26: =M26+N26 -> 9500000 | P26: USD | Q26: 출고 | R26: 완 | S26: 입금완료 | T26: 6530 | U26: 1435 | V26: 1770 | Z26: =SUM(T26,V26:Y26) -> 8300 | AA26: =SUM(AF26+AH26+AJ26+AK26-AL26) -> 0 | AB26: =SUM(AA26-Z26) -> -8300 | AM26: 35000 | AN26: 30000 | AR26: =SUM(AM26:AQ26) -> 65000 | AS26: =SUM(Z26-V26)*U26-AR26 -> 9305550 | AT26: =SUM(AS26-O26) -> -194450 | AU26: =SUM(M26*0.09) -> 855000 | AV26: =SUM(AT26:AU26)/2 -> 330275 | AW26: =AV26-(AV26*10%) -> 297247.5 | AX26: 50000 | AZ26: =SUM(AW26-AX26-AY26) -> 247247.5
A27: 26 | B27: 46028 | C27: QM6 | D27: 21도7330 | E27: KNME5C2M2HP011609 | F27: 카즈모터스 / 손성연 | H27: Faturat Net Sh.p.k | I27: Faturat Net Sh.p.k | J27: 811577636 | K27: +38349930085, +38344371274 | L27: Kosovo | M27: 8500000 | N27: 0 | O27: =M27+N27 -> 8500000 | P27: USD | Q27: 출고 | R27: 완 | S27: 입금완료 | T27: 5980 | U27: 1432 | V27: 1770 | Z27: =SUM(T27,V27:Y27) -> 7750 | AA27: =SUM(AF27+AH27+AJ27+AK27-AL27) -> 0 | AB27: =SUM(AA27-Z27) -> -7750 | AM27: 35000 | AN27: 30000 | AR27: =SUM(AM27:AQ27) -> 65000 | AS27: =SUM(Z27-V27)*U27-AR27 -> 8498360 | AT27: =SUM(AS27-O27) -> -1640 | AU27: =SUM(M27*0.09) -> 765000 | AV27: =SUM(AT27:AU27)/2 -> 381680 | AW27: =AV27-(AV27*10%) -> 343512 | AX27: 50000 | AZ27: =SUM(AW27-AX27-AY27) -> 293512
A28: 27 | B28: 46028 | C28: TUCSON | D28: 68주5530 | E28: KMHJ3815GGU067550 | F28: 삼일모터스 / 박홍균 | H28: AUTO-ANDI | I28: Andi Cereku | J28: M34710201A | K28: 696688738 | L28: Albania | M28: 6500000 | N28: 0 | O28: =M28+N28 -> 6500000 | P28: USD | Q28: 출고 | R28: 완 | S28: 입금완료 | T28: 4530 | U28: 1435 | V28: 1770 | Z28: =SUM(T28,V28:Y28) -> 6300 | AA28: =SUM(AF28+AH28+AJ28+AK28-AL28) -> 0 | AB28: =SUM(AA28-Z28) -> -6300 | AM28: 35000 | AN28: 30000 | AR28: =SUM(AM28:AQ28) -> 65000 | AS28: =SUM(Z28-V28)*U28-AR28 -> 6435550 | AT28: =SUM(AS28-O28) -> -64450 | AU28: =SUM(M28*0.09) -> 585000 | AV28: =SUM(AT28:AU28)/2 -> 260275 | AW28: =AV28-(AV28*10%) -> 234247.5 | AX28: 50000 | AZ28: =SUM(AW28-AX28-AY28) -> 184247.5
A29: 28 | B29: 46030 | C29: A6 45 TDI | D29: 243도6391 | E29: WAUZZZF25LN051265 | F29: 스카이모터스 원주희 | H29: AUTO-ANDI | I29: Andi Cereku | J29: M34710201A | K29: 696688738 | L29: Albania | M29: 31200000 | N29: 0 | O29: =M29+N29 -> 31200000 | P29: USD | Q29: 출고 | R29: 완 | S29: 입금완료 | T29: 20830 | U29: 1435 | V29: 1670 | Z29: =SUM(T29,V29:Y29) -> 22500 | AA29: =SUM(AF29+AH29+AJ29+AK29-AL29) -> 0 | AB29: =SUM(AA29-Z29) -> -22500 | AM29: 35000 | AN29: 30000 | AR29: =SUM(AM29:AQ29) -> 65000 | AS29: =SUM(Z29-V29)*U29-AR29 -> 29826050 | AT29: =SUM(AS29-O29) -> -1373950 | AU29: =SUM(M29*0.09) -> 2808000 | AV29: =SUM(AT29:AU29)/2 -> 717025 | AW29: =AV29-(AV29*10%) -> 645322.5 | AX29: 50000 | AZ29: =SUM(AW29-AX29-AY29) -> 595322.5
A30: 29 | B30: 46031 | C30: Velar D300 | D30: 46라2219 | E30: SALYA2BK1JA732832 | F30: 아이오토스 / 선민중 | H30: Faturat Net Sh.p.k | I30: Faturat Net Sh.p.k | J30: 811577636 | K30: +38349930085, +38344371274 | L30: Kosovo | M30: 32660000 | N30: 0 | O30: =M30+N30 -> 32660000 | P30: USD | Q30: 출고 | R30: 완 | S30: 입금완료 | T30: 22030 | U30: 1435 | Z30: =SUM(T30,V30:Y30) -> 22030 | AA30: =SUM(AF30+AH30+AJ30+AK30-AL30) -> 0 | AB30: =SUM(AA30-Z30) -> -22030 | AM30: 35000 | AN30: 30000 | AR30: =SUM(AM30:AQ30) -> 65000 | AS30: =SUM(Z30-V30)*U30-AR30 -> 31548050 | AT30: =SUM(AS30-O30) -> -1111950 | AU30: =SUM(M30*0.09) -> 2939400 | AV30: =SUM(AT30:AU30)/2 -> 913725 | AW30: =AV30-(AV30*10%) -> 822352.5 | AX30: 50000 | AZ30: =SUM(AW30-AX30-AY30) -> 772352.5
A31: 30 | B31: 46032 | C31: A6 40 TDI | D31: 35다0560 | E31: WAUZZZ4GXGN021988 | F31: 강창희 | H31: AUTO-ANDI | I31: Andi Cereku | J31: M34710201A | K31: 696688738 | L31: Albania | M31: 7100000 | N31: 0 | O31: =M31+N31 -> 7100000 | P31: USD | Q31: 출고 | R31: 완 | S31: 입금완료 | T31: 5230 | U31: 1439 | V31: 1670 | Z31: =SUM(T31,V31:Y31) -> 6900 | AA31: =SUM(AF31+AH31+AJ31+AK31-AL31) -> 0 | AB31: =SUM(AA31-Z31) -> -6900 | AM31: 35000 | AN31: 30000 | AR31: =SUM(AM31:AQ31) -> 65000 | AS31: =SUM(Z31-V31)*U31-AR31 -> 7460970 | AT31: =SUM(AS31-O31) -> 360970 | AU31: =SUM(M31*0.09) -> 639000 | AV31: =SUM(AT31:AU31)/2 -> 499985 | AW31: =AV31-(AV31*10%) -> 449986.5 | AX31: 50000 | AZ31: =SUM(AW31-AX31-AY31) -> 399986.5
A32: 31 | B32: 46035 | C32: C-CLASS | D32: 47소5093 | E32: WDDWF0EB6FF125289 | F32: 셀링오토 곽철희 | H32: AUTO-ANDI | I32: Andi Cereku | J32: M34710201A | K32: 696688738 | L32: Albania | M32: 10400000 | N32: 0 | O32: =M32+N32 -> 10400000 | P32: USD | Q32: 출고 | R32: 완 | S32: 입금완료 | T32: 7030 | U32: 1465 | V32: 1670 | Z32: =SUM(T32,V32:Y32) -> 8700 | AA32: =SUM(AF32+AH32+AJ32+AK32-AL32) -> 0 | AB32: =SUM(AA32-Z32) -> -8700 | AM32: 35000 | AN32: 30000 | AR32: =SUM(AM32:AQ32) -> 65000 | AS32: =SUM(Z32-V32)*U32-AR32 -> 10233950 | AT32: =SUM(AS32-O32) -> -166050 | AU32: =SUM(M32*0.09) -> 936000 | AV32: =SUM(AT32:AU32)/2 -> 384975 | AW32: =AV32-(AV32*10%) -> 346477.5 | AX32: 50000 | AZ32: =SUM(AW32-AX32-AY32) -> 296477.5
A33: 32 | B33: 46037 | C33: Q5 | D33: 63버1609 | E33: WAUZZZ8R8FA064534 | F33: 주식회사 회성무역 | H33: AUTO-ANDI | I33: Andi Cereku | J33: M34710201A | K33: 696688738 | L33: Albania | M33: 8600000 | N33: 0 | O33: =M33+N33 -> 8600000 | P33: USD | Q33: 출고 | R33: 완 | S33: 입금완료 | T33: 5930 | U33: 1465 | V33: 1770 | Z33: =SUM(T33,V33:Y33) -> 7700 | AA33: =SUM(AF33+AH33+AJ33+AK33-AL33) -> 0 | AB33: =SUM(AA33-Z33) -> -7700 | AM33: 35000 | AN33: 30000 | AR33: =SUM(AM33:AQ33) -> 65000 | AS33: =SUM(Z33-V33)*U33-AR33 -> 8622450 | AT33: =SUM(AS33-O33) -> 22450 | AU33: =SUM(M33*0.09) -> 774000 | AV33: =SUM(AT33:AU33)/2 -> 398225 | AW33: =AV33-(AV33*10%) -> 358402.5 | AX33: 50000 | AZ33: =SUM(AW33-AX33-AY33) -> 308402.5
A34: 33 | B34: 46049 | C34: 320D GT | D34: 38거3214 | E34: WBA8T5102JG819703 | F34: MS 모터스 / 황용연 | H34: Faturat Net Sh.p.k | I34: Faturat Net Sh.p.k | J34: 811577636 | K34: +38349930085, +38344371274 | L34: Kosovo | M34: 10500000 | N34: 0 | O34: =M34+N34 -> 10500000 | P34: USD | Q34: 출고 | R34: 완 | S34: 입금완료 | T34: 7080 | U34: 1454 | Z34: =SUM(T34,V34:Y34) -> 7080 | AA34: =SUM(AF34+AH34+AJ34+AK34-AL34) -> 0 | AB34: =SUM(AA34-Z34) -> -7080 | AM34: 35000 | AN34: 30000 | AR34: =SUM(AM34:AQ34) -> 65000 | AS34: =SUM(Z34-V34)*U34-AR34 -> 10229320 | AT34: =SUM(AS34-O34) -> -270680 | AU34: =SUM(M34*0.09) -> 945000 | AV34: =SUM(AT34:AU34)/2 -> 337160 | AW34: =AV34-(AV34*10%) -> 303444 | AX34: 50000 | AZ34: =SUM(AW34-AX34-AY34) -> 253444
A35: 34 | B35: 46054 | C35: A7 45 TDI | D35: 54서2846 | E35: WAUZZZ4G9FN006056 | F35: 셀링오토 / 곽철희 | H35: AUTO-ANDI | I35: Andi Cereku | J35: M34710201A | K35: 696688738 | L35: Albania | M35: 8300000 | N35: 0 | O35: =M35+N35 -> 8300000 | P35: USD | Q35: 출고 | R35: 완 | S35: 입금완료 | T35: 5930 | U35: 1439 | V35: 1670 | Z35: =SUM(T35,V35:Y35) -> 7600 | AA35: =SUM(AF35+AH35+AJ35+AK35-AL35) -> 0 | AB35: =SUM(AA35-Z35) -> -7600 | AM35: 35000 | AN35: 30000 | AR35: =SUM(AM35:AQ35) -> 65000 | AS35: =SUM(Z35-V35)*U35-AR35 -> 8468270 | AT35: =SUM(AS35-O35) -> 168270 | AU35: =SUM(M35*0.09) -> 747000 | AV35: =SUM(AT35:AU35)/2 -> 457635 | AW35: =AV35-(AV35*10%) -> 411871.5 | AX35: 50000 | AZ35: =SUM(AW35-AX35-AY35) -> 361871.5
A36: 35 | B36: 46054 | C36: C-CLASS | D36: 362다7392 | E36: WDDWF0EB7FF111353 | F36: 하이앤드모터스 / 배형빈 | H36: AUTO-ANDI | I36: Andi Cereku | J36: M34710201A | K36: 696688738 | L36: Albania | M36: 11800000 | N36: 0 | O36: =M36+N36 -> 11800000 | P36: USD | Q36: 출고 | R36: 완 | S36: 입금완료 | T36: 7980 | U36: 1439 | V36: 1670 | Z36: =SUM(T36,V36:Y36) -> 9650 | AA36: =SUM(AF36+AH36+AJ36+AK36-AL36) -> 0 | AB36: =SUM(AA36-Z36) -> -9650 | AM36: 35000 | AN36: 30000 | AR36: =SUM(AM36:AQ36) -> 65000 | AS36: =SUM(Z36-V36)*U36-AR36 -> 11418220 | AT36: =SUM(AS36-O36) -> -381780 | AU36: =SUM(M36*0.09) -> 1062000 | AV36: =SUM(AT36:AU36)/2 -> 340110 | AW36: =AV36-(AV36*10%) -> 306099 | AX36: 50000 | AZ36: =SUM(AW36-AX36-AY36) -> 256099
A37: 36 | B37: 46056 | C37: GLE350 D | D37: 33너2761 | E37: WDCED2EB4HA069189 | F37: 대박모터스 / 윤창기 | H37: AUTO-ANDI | I37: Andi Cereku | J37: M34710201A | K37: 696688738 | L37: Albania | M37: 27700000 | N37: 0 | O37: =M37+N37 -> 27700000 | P37: USD | Q37: 출고 | R37: 완 | S37: 입금완료 | T37: 18330 | U37: 1439 | V37: 1870 | Z37: =SUM(T37,V37:Y37) -> 20200 | AA37: =SUM(AF37+AH37+AJ37+AK37-AL37) -> 0 | AB37: =SUM(AA37-Z37) -> -20200 | AM37: 35000 | AN37: 30000 | AR37: =SUM(AM37:AQ37) -> 65000 | AS37: =SUM(Z37-V37)*U37-AR37 -> 26311870 | AT37: =SUM(AS37-O37) -> -1388130 | AU37: =SUM(M37*0.09) -> 2493000 | AV37: =SUM(AT37:AU37)/2 -> 552435 | AW37: =AV37-(AV37*10%) -> 497191.5 | AX37: 50000 | AZ37: =SUM(AW37-AX37-AY37) -> 447191.5
A38: 37 | B38: 46072 | C38: Passat GT 2.0TDI | D38: 280조1895 | E38: WWWZZZ3CZNE028333 | F38: 준모터스 / 김미란 | H38: Faturat Net Sh.p.k | I38: Faturat Net Sh.p.k | J38: 811577636 | K38: +38349930085, +38344371274 | L38: Kosovo | M38: 24400000 | N38: 0 | O38: =M38+N38 -> 24400000 | P38: USD | Q38: 출고 | R38: 완 | S38: 입금완료 | T38: 16630 | U38: 1436 | Z38: =SUM(T38,V38:Y38) -> 16630 | AA38: =SUM(AF38+AH38+AJ38+AK38-AL38) -> 0 | AB38: =SUM(AA38-Z38) -> -16630 | AM38: 35000 | AN38: 30000 | AR38: =SUM(AM38:AQ38) -> 65000 | AS38: =SUM(Z38-V38)*U38-AR38 -> 23815680 | AT38: =SUM(AS38-O38) -> -584320 | AU38: =SUM(M38*0.09) -> 2196000 | AV38: =SUM(AT38:AU38)/2 -> 805840 | AW38: =AV38-(AV38*10%) -> 725256 | AX38: 50000 | AZ38: =SUM(AW38-AX38-AY38) -> 675256
A39: 38 | B39: 46072 | C39: GRANDEUR | D39: 176다7273 | E39: KMHN341FBPA055016 | F39: 신원모터스 / 원도형 | H39: AUTO-ANDI | I39: Meta andi | J39: J00629078J | K39: 696688738 | L39: Albania | M39: 23200000 | N39: 0 | O39: =M39+N39 -> 23200000 | P39: USD | Q39: 출고 | R39: 완 | S39: 입금완료 | T39: 15480 | U39: 1436 | V39: 1370 | Z39: =SUM(T39,V39:Y39) -> 16850 | AA39: =SUM(AF39+AH39+AJ39+AK39-AL39) -> 0 | AB39: =SUM(AA39-Z39) -> -16850 | AM39: 35000 | AN39: 30000 | AR39: =SUM(AM39:AQ39) -> 65000 | AS39: =SUM(Z39-V39)*U39-AR39 -> 22164280 | AT39: =SUM(AS39-O39) -> -1035720 | AU39: =SUM(M39*0.09) -> 2088000 | AV39: =SUM(AT39:AU39)/2 -> 526140 | AW39: =AV39-(AV39*10%) -> 473526 | AX39: 50000 | AZ39: =SUM(AW39-AX39-AY39) -> 423526
A40: 39 | B40: 46076 | C40: A4 | D40: 64노9633 | E40: WAUZZZ8K9EA097754 | F40: 서진모터스 / 이수욱 | H40: AUTO-ANDI | I40: Markeci Federiko | J40: K80110056Q | K40: 696688738 | L40: Albania | M40: 5700000 | N40: 0 | O40: =M40+N40 -> 5700000 | Q40: 출고 | R40: 완 | S40: 입금완료 | T40: 3900 | U40: 1434 | V40: 1370 | Z40: =SUM(T40,V40:Y40) -> 5270 | AA40: =SUM(AF40+AH40+AJ40+AK40-AL40) -> 0 | AB40: =SUM(AA40-Z40) -> -5270 | AM40: 35000 | AN40: 30000 | AR40: =SUM(AM40:AQ40) -> 65000 | AS40: =SUM(Z40-V40)*U40-AR40 -> 5527600 | AT40: =SUM(AS40-O40) -> -172400 | AU40: =SUM(M40*0.09) -> 513000 | AV40: =SUM(AT40:AU40)/2 -> 170300 | AW40: =AV40-(AV40*10%) -> 153270 | AX40: 50000 | AZ40: =SUM(AW40-AX40-AY40) -> 103270
...

Sheet 달러 인보이스+판매보고AUTO
E1: PROFORM INVOICE | H1: 83 | I1: 판매보고 자동화 (AUTO)
A2: Ssancar LTD 46-1, Gakgol-ro 2an-Gil, Sangnok, Ansan-si, Gyeinggi-do, Incheon, Korea. Phone: +82-505-366-9977 | I2: 매매단지 매입➖➖➖➖➖➖➖➖➖➖➖➖➖
E3: Date | F3: =VLOOKUP($H$1,'달러 판매현황'!A2:BA241,2,FALSE) -> 46190 | I3: ="차량명 : " & VLOOKUP($H$1,'달러 판매현황'!A2:BA241,3,FALSE) -> 차량명 : E-CLASS
E4: Invoice No. | F4: ="YB"&RIGHT(C18,6) -> YB093089 | I4: ="차량번호 : " & TEXT(VLOOKUP($H$1,'달러 판매현황'!A1:BA240,4,FALSE),"#,##0") -> 차량번호 : 190머9766
E5: Name | F5: =VLOOKUP($H$1,'달러 판매현황'!A2:BA241,9,FALSE) -> Faturat Net Sh.p.k | I5: ="차대번호 : " & TEXT(VLOOKUP($H$1,'달러 판매현황'!A2:BA241,5,FALSE),"#,##0") -> 차대번호 : WDDZ0EB5HA093089
E6: ID No. / business No. | F6: =VLOOKUP($H$1,'달러 판매현황'!A2:BA242,10,FALSE) -> 811577636 | I6: ="차량대금 : " & TEXT(VLOOKUP($H$1,'달러 판매현황'!A2:BA241,13,FALSE),"#,##0") & "원" -> 차량대금 : 17,500,000원
E7: Address | F7: =VLOOKUP($H$1,'달러 판매현황'!A2:BA243,12,FALSE) -> Kosovo | I7: ="매도비 : "&VLOOKUP($H$1,'달러 판매현황'!A3:BA242,14,FALSE)&"원" -> 매도비 : 0원
E8: Country | F8: =VLOOKUP($H$1,'달러 판매현황'!A2:BA241,12,FALSE) -> Kosovo | I8: 계산서 : 100%
E9: Phone | F9: =VLOOKUP($H$1,'달러 판매현황'!A2:BA245,11,FALSE) -> +38349930085, +38344371274 | I9: ="판매처 : " & VLOOKUP($H$1,'달러 판매현황'!A5:BA244,6,FALSE) -> 판매처 : 세이프티중고차 / 장순주
E10: Dollar exchange rate | F10: =VLOOKUP($H$1,'달러 판매현황'!A2:BA241,21,FALSE) -> 1505 | I10: ="바이어 : " & VLOOKUP($H$1,'달러 판매현황'!A5:BA244,8,FALSE) -> 바이어 : Faturat Net Sh.p.k
I11: ="판매금액 : $" & TEXT(VLOOKUP($H$1,'달러 판매현황'!A2:BA245,20,FALSE),"#,##0") -> 판매금액 : $11,410
A12: BANK ACCOUNT INFORMATION | I12: 배송조건 : CFR
A13: Beneficiary | C13: SSANCAR CO LTD | E13: Bank Name | F13: SHINHAN BANK | I13: ="환율 : $" & VLOOKUP($H$1,'달러 판매현황'!A2:BA245,21,FALSE) -> 환율 : $1505
A14: Swift Cose | C14: SHBKKRSE | E14: Bank Adress | F14: 20,Sejong-Daero9-Gil,Jung-Gu Seoul South Korea | I14: ="운임비 : $" & TEXT(VLOOKUP($H$1,'달러 판매현황'!A2:BA245,22,FALSE),"#,##0") -> 운임비 : $1,640
A15: Bank Account Number | C15: 180-008-400167 | E15: Beneficiary Adress | F15: 65 SEONGHYEON-RO,ILSANDONG-GU,GOYANG-SI, GYEONGGI-DO, SOUTH KOREA | I15: ="토탈 입금 받을금액 : $" & TEXT(VLOOKUP($H$1,'달러 판매현황'!A2:BA245,26,FALSE),"#,##0") -> 토탈 입금 받을금액 : $13,050
I16: ="계약금" & TEXT(VLOOKUP($H$1,'달러 판매현황'!A2:BA245,7,FALSE),"#,##0") -> 계약금회사100
A17: Code | B17: Model | C17: Chassis Number | D17: CAR PRICE | E17: Shipping Cost | F17: Total
A18: =VLOOKUP($H$1,'달러 판매현황'!A2:BA242,4,FALSE) -> 190머9766 | B18: =VLOOKUP($H$1,'달러 판매현황'!A2:BA242,3,FALSE) -> E-CLASS | C18: =VLOOKUP($H$1,'달러 판매현황'!A2:BA242,5,FALSE) -> WDDZ0EB5HA093089 | D18: =VLOOKUP($H$1,'달러 판매현황'!A2:BA241,20,FALSE) -> 11410 | E18: =VLOOKUP($H$1,'달러 판매현황'!A2:BA241,22,FALSE) -> 1640 | F18: =SUM(D18:E18) -> 13050
E31: Subtotal | F31: =SUM(F18:G30) -> 13050
E32: replacement cost | F32: -
E33: Commission | F33: -
E35: Total | F35: =SUM(F31:G34) -> 13050

Sheet 유로 판매현황
A1: NO | B1: 구입일자 | C1: CAR NAME | D1: 차량번호 | E1: WBAJC310 | F1: 판매자 정보 | G1: 계약금 | H1: 구입금액 | I1: 매도비 | J1: 총 구입금액 | K1: 상태 | L1: 판매보고 여부 | M1: 바이어 회사명 | N1: 고객컨사이니 | O1: 고객 ID / 비즈니스 넘버 | P1: 전화번호 | Q1: 주소 | R1: 나라 | S1: 입금여부 | T1: 판매금액 | U1: 환율 EURO | V1: 환율 USD | W1: 운임 | X1: 배송 | Y1: 디스카운트 | Z1: 인보이스 금액 | AA1: 판매 총 합계 | AB1: 입금합계 | AC1: 선수금 | AD1: 메모 | AE1: 메모 | AF1: 입금날짜01 | AG1: 정산01 | AH1: 입금날짜02 | AI1: 정산02 | AJ1: 입금날짜03 | AK1: 정산03 | AL1: 적립금 사용 | AM1: 선수금 | AN1: 말소/면허 | AO1: 탁송 | AP1: 캐리어 | AQ1: 쇼링 | AR1: 기타 | AS1: 합계 | AT1: 정산판매금 원화 | AU1: 판매마진 | AV1: 부가세 마진 | AW1: 총 마진 | AX1: 지급액 | AY1: 서류공제 | AZ1: 비용공제 | BA1: 실지급액 | BB1: 돈받은거
A2: 2 | B2: 46113 | C2: E-CLASS | D2: 18모1709 | E2: WDDHF0CBXEA918795 | F2: AJ | G2: ="YB"&RIGHT(#REF!,6) -> #REF! | H2: 6000000 | I2: 165000 | J2: =H2+I2 -> 6165000 | K2: 인천항 | L2: 완 | M2: Ramadan Xhaferi | N2: Balla Eni | O2: J00630041G | P2: +355 692079087 | Q2: Lagja 13 , plazh Albania | R2: Albania | S2: 50%적용/ 쉬핑제외 | T2: 3580 | U2: 1738 | V2: 1499 | W2: 0 | AA2: =SUM(T2,W2:Z2) -> 3580 | AB2: =SUM(AG2+AI2+AK2+AL2-AM2) -> 0 | AC2: =SUM(AB2-AA2) -> -3580 | AN2: 35000 | AO2: 30000 | AS2: =SUM(AN2:AR2) -> 65000 | AT2: =SUM(AA2-W2)*U2-AS2 -> 6157040 | AU2: =SUM(AT2-J2) -> -7960 | AV2: =SUM(0.09*H2) -> 540000 | AW2: =SUM(AU2:AV2)/2 -> 266020 | AX2: =AW2-(AW2*10%) -> 239418 | AY2: 50000 | BA2: =SUM(AX2-AY2-AZ2) -> 189418
A3: 3 | B3: 46113 | C3: A6 | D3: 64서3065 | E3: WAUZZZ4G0FN011534 | F3: AJ | G3: ="YB"&RIGHT(#REF!,6) -> #REF! | H3: 6450000 | I3: 166730 | J3: =H3+I3 -> 6616730 | K3: 인천항 | L3: 완 | M3: Ramadan Xhaferi | N3: MECANAJ ALBION | O3: K20217071W | P3: +355 692079087 | Q3: VLORE | R3: Albania | S3: 50%적용/ 쉬핑제외 | T3: 3830 | U3: 1738 | V3: 1499 | W3: 0 | AA3: =SUM(T3,W3:Z3) -> 3830 | AB3: =SUM(AG3+AI3+AK3+AL3-AM3) -> 0 | AC3: =SUM(AB3-AA3) -> -3830 | AN3: 35000 | AO3: 30000 | AS3: =SUM(AN3:AR3) -> 65000 | AT3: =SUM(AA3-W3)*U3-AS3 -> 6591540 | AU3: =SUM(AT3-J3) -> -25190 | AV3: =SUM(0.09*H3) -> 580500 | AW3: =SUM(AU3:AV3)/2 -> 277655 | AX3: =AW3-(AW3*10%) -> 249889.5 | AY3: 50000 | BA3: =SUM(AX3-AY3-AZ3) -> 199889.5
A4: 4 | B4: 46113 | C4: E-CLASS | D4: 16고6141 | E4: WDDHF8CB4EA910769 | F4: AJ | G4: ="YB"&RIGHT(#REF!,6) -> #REF! | H4: 6600000 | I4: 17610 | J4: =H4+I4 -> 6617610 | K4: 인천항 | L4: 완 | M4: Ramadan Xhaferi | N4: Erand derjaj | O4: J60818087L | P4: +355 692079087 | Q4: Lagja 13 , plazh Albania | R4: Albania | S4: 50%적용/ 쉬핑제외 | T4: 3930 | U4: 1738 | V4: 1499 | W4: 0 | AA4: =SUM(T4,W4:Z4) -> 3930 | AB4: =SUM(AG4+AI4+AK4+AL4-AM4) -> 0 | AC4: =SUM(AB4-AA4) -> -3930 | AN4: 35000 | AO4: 30000 | AS4: =SUM(AN4:AR4) -> 65000 | AT4: =SUM(AA4-W4)*U4-AS4 -> 6765340 | AU4: =SUM(AT4-J4) -> 147730 | AV4: =SUM(0.09*H4) -> 594000 | AW4: =SUM(AU4:AV4)/2 -> 370865 | AX4: =AW4-(AW4*10%) -> 333778.5 | AY4: 50000 | BA4: =SUM(AX4-AY4-AZ4) -> 283778.5
A5: 5 | B5: 46114 | C5: S-CLASS | D5: 175모8928 | E5: WDDUF3DB5FA158307 | F5: 차카/허재 | G5: ="YB"&RIGHT(#REF!,6) -> #REF! | H5: 24500000 | I5: 0 | J5: =H5+I5 -> 24500000 | K5: 인천항 | L5: 완 | M5: AUTO SHQIPONZA | N5: Allko esirald | O5: M43428202S | P5: +0696591358 | Q5: DURRES POST | R5: Albania | S5: 미수 | T5: 13370 | U5: 1738 | V5: 1499 | W5: 1380 | AA5: =SUM(T5,W5:Z5) -> 14750 | AB5: =SUM(AG5+AI5+AK5+AL5-AM5) -> 0 | AC5: =SUM(AB5-AA5) -> -14750 | AN5: 35000 | AO5: 30000 | AS5: =SUM(AN5:AR5) -> 65000 | AT5: =SUM(AA5-W5)*U5-AS5 -> 23172060 | AU5: =SUM(AT5-J5) -> -1327940 | AV5: =SUM(0.09*H5) -> 2205000 | AW5: =SUM(AU5:AV5)/2 -> 438530 | AX5: =AW5-(AW5*10%) -> 394677 | AY5: 50000 | BA5: =SUM(AX5-AY5-AZ5) -> 344677
A6: 6 | B6: 46114 | C6: GOLF | D6: 21로5718 | E6: WVWZZZAUZEW226952 | F6: 솔카/천승호 | G6: ="YB"&RIGHT(#REF!,6) -> #REF! | H6: 4500000 | I6: 0 | J6: =H6+I6 -> 4500000 | K6: 인천항 | L6: 완 | M6: AUTO SHQIPONZA | N6: Allko esirald | O6: M43428202S | P6: +0696591358 | Q6: DURRES POST | R6: Albania | S6: 미수 | T6: 2600 | U6: 1738 | V6: 1499 | W6: 1300 | AA6: =SUM(T6,W6:Z6) -> 3900 | AB6: =SUM(AG6+AI6+AK6+AL6-AM6) -> 0 | AC6: =SUM(AB6-AA6) -> -3900 | AN6: 35000 | AO6: 30000 | AS6: =SUM(AN6:AR6) -> 65000 | AT6: =SUM(AA6-W6)*U6-AS6 -> 4453800 | AU6: =SUM(AT6-J6) -> -46200 | AV6: =SUM(0.09*H6) -> 405000 | AW6: =SUM(AU6:AV6)/2 -> 179400 | AX6: =AW6-(AW6*10%) -> 161460 | AY6: 50000 | BA6: =SUM(AX6-AY6-AZ6) -> 111460
A7: 7 | B7: 46114 | C7: A6 40 TDI | D7: 380누8232 | E7: WAUZZZ4G3GN167195 | F7: 오토웨이/박병학 | G7: ="YB"&RIGHT(#REF!,6) -> #REF! | H7: 13340000 | I7: 0 | J7: =H7+I7 -> 13340000 | K7: 인천항 | L7: 완 | M7: FER-GROUP SH.P.K | N7: FERGROUP SHPK | O7: 811054999 | P7: ‪+383 48 238888‪ | Q7: DURRES POST | R7: Kosovo | S7: 입금완료 | T7: 7550 | U7: 1738 | V7: 1499 | W7: 1300 | AA7: =SUM(T7,W7:Z7) -> 8850 | AB7: =SUM(AG7+AI7+AK7+AL7-AM7) -> 0 | AC7: =SUM(AB7-AA7) -> -8850 | AN7: 35000 | AO7: 30000 | AS7: =SUM(AN7:AR7) -> 65000 | AT7: =SUM(AA7-W7)*U7-AS7 -> 13056900 | AU7: =SUM(AT7-J7) -> -283100 | AV7: =SUM(0.09*H7) -> 1200600 | AW7: =SUM(AU7:AV7)/2 -> 458750 | AX7: =AW7-(AW7*10%) -> 412875 | AY7: 50000 | BA7: =SUM(AX7-AY7-AZ7) -> 362875
A8: 8 | B8: 46114 | C8: A7 3.0 TDI | D8: 287저2966 | E8: WAUZZZ4G1DN081010 | F8: 신원자동차/정환석 | G8: ="YB"&RIGHT(#REF!,6) -> #REF! | H8: 8640000 | I8: 0 | J8: =H8+I8 -> 8640000 | K8: 인천항 | L8: 완 | M8: AUTO SHQIPONZA | N8: Allko esirald | O8: M43428202S | P8: +0696591358 | Q8: DURRES POST | R8: Albania | S8: 미수 | T8: 4800 | U8: 1738 | V8: 1499 | W8: 1300 | AA8: =SUM(T8,W8:Z8) -> 6100 | AB8: =SUM(AG8+AI8+AK8+AL8-AM8) -> 0 | AC8: =SUM(AB8-AA8) -> -6100 | AN8: 35000 | AO8: 30000 | AS8: =SUM(AN8:AR8) -> 65000 | AT8: =SUM(AA8-W8)*U8-AS8 -> 8277400 | AU8: =SUM(AT8-J8) -> -362600 | AV8: =SUM(0.09*H8) -> 777600 | AW8: =SUM(AU8:AV8)/2 -> 207500 | AX8: =AW8-(AW8*10%) -> 186750 | AY8: 50000 | BA8: =SUM(AX8-AY8-AZ8) -> 136750
A9: 9 | B9: 46114 | C9: TIGUAN | D9: 32소9154 | E9: WVGZZZ5NZAW095741 | F9: AJ | G9: ="YB"&RIGHT(#REF!,6) -> #REF! | H9: 2800000 | I9: 165000 | J9: =H9+I9 -> 2965000 | K9: 인천항 | L9: 완 | M9: AUTO SHQIPONZA | N9: Allko esirald | O9: M43428202S | P9: +0696591358 | Q9: DURRES POST | R9: Albania | S9: 미수 | T9: 2170 | U9: 1738 | V9: 1499 | W9: 1380 | AA9: =SUM(T9,W9:Z9) -> 3550 | AB9: =SUM(AG9+AI9+AK9+AL9-AM9) -> 0 | AC9: =SUM(AB9-AA9) -> -3550 | AN9: 35000 | AO9: 30000 | AS9: =SUM(AN9:AR9) -> 65000 | AT9: =SUM(AA9-W9)*U9-AS9 -> 3706460 | AU9: =SUM(AT9-J9) -> 741460 | AV9: =SUM(0.09*H9) -> 252000 | AW9: =SUM(AU9:AV9)/2 -> 496730 | AX9: =AW9-(AW9*10%) -> 447057 | AY9: 50000 | BA9: =SUM(AX9-AY9-AZ9) -> 397057
A10: 10 | B10: 46114 | C10: E-CLASS | D10: 340고3006 | E10: WDDHF9EB5FB098588 | F10: KCAR | G10: ="YB"&RIGHT(#REF!,6) -> #REF! | H10: 7300000 | I10: 165000 | J10: =H10+I10 -> 7465000 | K10: 인천항 | L10: 완 | M10: AUTO SHQIPONZA | N10: Allko esirald | O10: M43428202S | P10: +0696591358 | Q10: DURRES POST | R10: Albania | T10: =6500-1285 -> 5215 | U10: 1738 | V10: 1499 | W10: 1285 | AA10: =SUM(T10,W10:Z10) -> 6500 | AB10: =SUM(AG10+AI10+AK10+AL10-AM10) -> 0 | AC10: =SUM(AB10-AA10) -> -6500 | AN10: 35000 | AO10: 30000 | AS10: =SUM(AN10:AR10) -> 65000 | AT10: =SUM(AA10-W10)*U10-AS10 -> 8998670 | AU10: =SUM(AT10-J10) -> 1533670 | AV10: =SUM(0.09*H10) -> 657000 | AW10: =SUM(AU10:AV10)/2 -> 1095335 | AX10: =AW10-(AW10*10%) -> 985801.5 | AY10: 50000 | BA10: =SUM(AX10-AY10-AZ10) -> 935801.5
A11: 11 | B11: 46118 | C11: 640D | D11: 45거3724 | E11: WBA6E4101GD929387 | F11: 스카이모터스 / 송민서 | G11: ="YB"&RIGHT(#REF!,6) -> #REF! | H11: 15000000 | I11: 0 | J11: =H11+I11 -> 15000000 | K11: 인천항 | L11: 완 | M11: AUTO SHQIPONZA | N11: Allko esirald | O11: M43428202S | P11: +0696591358 | Q11: DURRES POST | R11: Albania | S11: 미수 | T11: 8200 | U11: 1722 | V11: 1495 | W11: 1300 | AA11: =SUM(T11,W11:Z11) -> 9500 | AB11: =SUM(AG11+AI11+AK11+AL11-AM11) -> 0 | AC11: =SUM(AB11-AA11) -> -9500 | AN11: 35000 | AO11: 30000 | AS11: =SUM(AN11:AR11) -> 65000 | AT11: =SUM(AA11-W11)*U11-AS11 -> 14055400 | AU11: =SUM(AT11-J11) -> -944600 | AV11: =SUM(0.09*H11) -> 1350000 | AW11: =SUM(AU11:AV11)/2 -> 202700 | AX11: =AW11-(AW11*10%) -> 182430 | AY11: 50000 | BA11: =SUM(AX11-AY11-AZ11) -> 132430
A12: 12 | B12: 46118 | C12: EVOQUE | D12: 06누0302 | E12: SALVA2BN6GH136032 | F12: 현진모터스/유현진 | G12: ="YB"&RIGHT(#REF!,6) -> #REF! | H12: 12800000 | I12: 0 | J12: =H12+I12 -> 12800000 | K12: 인천항 | L12: 완 | M12: AUTO SHQIPONZA | N12: Bicaku Elda | O12: K35923063B | P12: +0696591358 | Q12: DURRES POST | R12: Albania | S12: 미수 | T12: 7020 | U12: 1722 | V12: 1495 | W12: 1380 | AA12: =SUM(T12,W12:Z12) -> 8400 | AB12: 8400 | AC12: =SUM(AB12-AA12) -> 0 | AN12: 35000 | AO12: 30000 | AS12: =SUM(AN12:AR12) -> 65000 | AT12: =SUM(AA12-W12)*U12-AS12 -> 12023440 | AU12: =SUM(AT12-J12) -> -776560 | AV12: =SUM(0.09*H12) -> 1152000 | AW12: =SUM(AU12:AV12)/2 -> 187720 | AX12: =AW12-(AW12*10%) -> 168948 | AY12: 50000 | BA12: =SUM(AX12-AY12-AZ12) -> 118948
A13: 13 | B13: 46118 | C13: TIGUAN | D13: 387무3733 | E13: WVGZZZ5NZLW319878 | F13: 블루오토/장기훈 | G13: . | H13: 17700000 | I13: 440000 | J13: =H13+I13 -> 18140000 | K13: 인천항 | L13: 완 | M13: AUTO SALLON TIKU-DITI SH.P.K | N13: Ibush Arifi | O13: 1011135761 | P13: +383 45 588 543 | Q13: ISMET KRASNIQI, 208, 10 Prishtine, Kosovo | R13: Kosovo | S13: 미수 4800. 6800입금 | T13: 10220 | U13: 1722 | V13: 1495 | W13: 1380 | AA13: =SUM(T13,W13:Z13) -> 11600 | AB13: =SUM(AG13+AI13+AK13+AL13-AM13) -> 0 | AC13: =SUM(AB13-AA13) -> -11600 | AN13: 35000 | AO13: 30000 | AS13: =SUM(AN13:AR13) -> 65000 | AT13: =SUM(AA13-W13)*U13-AS13 -> 17533840 | AU13: =SUM(AT13-J13) -> -606160 | AV13: =SUM(0.09*H13) -> 1593000 | AW13: =SUM(AU13:AV13)/2 -> 493420 | AX13: =AW13-(AW13*10%) -> 444078 | AY13: 50000 | BA13: =SUM(AX13-AY13-AZ13) -> 394078 | BB13: 0
A14: 14 | B14: 46118 | C14: Porsche Macan | D14: 287조5161 | E14: WP1AD2954FLB88336 | F14: 건모터스/김태혁 | G14: ="YB"&RIGHT(#REF!,6) -> #REF! | H14: 18900000 | I14: 0 | J14: =H14+I14 -> 18900000 | K14: 인천항 | L14: 완 | M14: AUTO SHQIPONZA | N14: Allko esirald | O14: M43428202S | P14: +0696591358 | Q14: DURRES POST | R14: Albania | S14: 미수 | T14: 10520 | U14: 1722 | V14: 1495 | W14: 1380 | AA14: =SUM(T14,W14:Z14) -> 11900 | AB14: =SUM(AG14+AI14+AK14+AL14-AM14) -> 0 | AC14: =SUM(AB14-AA14) -> -11900 | AN14: 35000 | AO14: 30000 | AS14: =SUM(AN14:AR14) -> 65000 | AT14: =SUM(AA14-W14)*U14-AS14 -> 18050440 | AU14: =SUM(AT14-J14) -> -849560 | AV14: =SUM(0.09*H14) -> 1701000 | AW14: =SUM(AU14:AV14)/2 -> 425720 | AX14: =AW14-(AW14*10%) -> 383148 | AY14: 50000 | BA14: =SUM(AX14-AY14-AZ14) -> 333148
A15: 15 | B15: 46118 | C15: A4 | D15: 193조6929 | E15: WAUZZZ8K0GA010729 | F15: 스마일자동차/김정훈 | G15: ="YB"&RIGHT(#REF!,6) -> #REF! | H15: 6600000 | I15: 0 | J15: =H15+I15 -> 6600000 | K15: 인천항 | L15: 완 | M15: Ramadan Xhaferi | N15: Hasan Sokoli | O15: J502020460 | P15: +355 692079087 | Q15: Lagja 13 , plazh Albania | R15: Albania | S15: 50%적용/ 쉬핑제외 | T15: 3800 | U15: 1722 | V15: 1495 | W15: 1380 | AA15: =SUM(T15,W15:Z15) -> 5180 | AB15: =SUM(AG15+AI15+AK15+AL15-AM15) -> 0 | AC15: =SUM(AB15-AA15) -> -5180 | AN15: 35000 | AO15: 30000 | AS15: =SUM(AN15:AR15) -> 65000 | AT15: =SUM(AA15-W15)*U15-AS15 -> 6478600 | AU15: =SUM(AT15-J15) -> -121400 | AV15: =SUM(0.09*H15) -> 594000 | AW15: =SUM(AU15:AV15)/2 -> 236300 | AX15: =AW15-(AW15*10%) -> 212670 | AY15: 50000 | BA15: =SUM(AX15-AY15-AZ15) -> 162670
A16: 16 | B16: 46118 | C16: GOLF | D16: 11도5235 | E16: WVWZZZAUZFW280737 | F16: 현대글로비스 | G16: ="YB"&RIGHT(#REF!,6) -> #REF! | H16: 6300000 | I16: 165000 | J16: =H16+I16 -> 6465000 | K16: 인천항 | L16: 완 | M16: Ramadan Xhaferi | N16: Hasan Sokoli | O16: J502020460 | P16: +355 692079087 | Q16: Lagja 13 , plazh Albania | R16: Albania | S16: 50%적용/ 쉬핑제외 | T16: 3800 | U16: 1722 | V16: 1495 | AA16: =SUM(T16,W16:Z16) -> 3800 | AB16: =SUM(AG16+AI16+AK16+AL16-AM16) -> 0 | AC16: =SUM(AB16-AA16) -> -3800 | AN16: 35000 | AO16: 30000 | AS16: =SUM(AN16:AR16) -> 65000 | AT16: =SUM(AA16-W16)*U16-AS16 -> 6478600 | AU16: =SUM(AT16-J16) -> 13600 | AV16: =SUM(0.09*H16) -> 567000 | AW16: =SUM(AU16:AV16)/2 -> 290300 | AX16: =AW16-(AW16*10%) -> 261270 | AY16: 50000 | BA16: =SUM(AX16-AY16-AZ16) -> 211270 | BB16: 0
A17: 17 | B17: 46120 | C17: CLS250D | D17: 298오9431 | E17: WDDLJ9HB3FA144977 | F17: AJ | G17: con10 | H17: 9750000 | I17: 252030 | J17: =H17+I17 -> 10002030 | K17: 인천항 | L17: 완 | M17: Ramadan Xhaferi | N17: Erand derjaj | O17: J60818087L | P17: +355 692079087 | Q17: Lagja 13 , plazh Albania | R17: Albania | S17: 50%적용/ 쉬핑제외 | T17: 5650 | U17: 1713 | V17: 1465 | AA17: =SUM(T17,W17:Z17) -> 5650 | AB17: =SUM(AG17+AI17+AK17+AL17-AM17) -> 0 | AC17: =SUM(AB17-AA17) -> -5650 | AN17: 35000 | AO17: 30000 | AS17: =SUM(AN17:AR17) -> 65000 | AT17: =SUM(AA17-W17)*U17-AS17 -> 9613450 | AU17: =SUM(AT17-J17) -> -388580 | AV17: =SUM(0.09*H17) -> 877500 | AW17: =SUM(AU17:AV17)/2 -> 244460 | AX17: =AW17-(AW17*10%) -> 220014 | AY17: 50000 | BA17: =SUM(AX17-AY17-AZ17) -> 170014
A18: 18 | B18: 46120 | C18: GOLF | D18: 11노1747 | E18: WVWZZZAUZFW271981 | F18: AJ | G18: con10 | H18: 5800000 | I18: 165000 | J18: =H18+I18 -> 5965000 | K18: 인천항 | L18: 완 | M18: Ramadan Xhaferi | N18: ELIDJON SULO | O18: J00116105A | P18: +355 692079087 | Q18: Lagja 13 , plazh Albania | R18: Albania | S18: 50%적용/ 쉬핑제외 | T18: 3480 | U18: 1713 | V18: 1465 | AA18: =SUM(T18,W18:Z18) -> 3480 | AB18: =SUM(AG18+AI18+AK18+AL18-AM18) -> 0 | AC18: =SUM(AB18-AA18) -> -3480 | AN18: 35000 | AO18: 30000 | AS18: =SUM(AN18:AR18) -> 65000 | AT18: =SUM(AA18-W18)*U18-AS18 -> 5896240 | AU18: =SUM(AT18-J18) -> -68760 | AV18: =SUM(0.09*H18) -> 522000 | AW18: =SUM(AU18:AV18)/2 -> 226620 | AX18: =AW18-(AW18*10%) -> 203958 | AY18: 50000 | BA18: =SUM(AX18-AY18-AZ18) -> 153958
A19: 19 | B19: 46120 | C19: GOLF | D19: 17소5786 | E19: WVWZZZAUZEW401738 | F19: AJ | G19: con10 | H19: 6550000 | I19: 169310 | J19: =H19+I19 -> 6719310 | K19: 인천항 | L19: 완 | M19: Ramadan Xhaferi | N19: COLLAKI KLESJO | O19: J90219059T | P19: +355 692079087 | Q19: ALBANIA | R19: Albania | S19: 50%적용/ 쉬핑제외 | T19: 3900 | U19: 1713 | V19: 1465 | AA19: =SUM(T19,W19:Z19) -> 3900 | AB19: =SUM(AG19+AI19+AK19+AL19-AM19) -> 0 | AC19: =SUM(AB19-AA19) -> -3900 | AN19: 35000 | AO19: 30000 | AS19: =SUM(AN19:AR19) -> 65000 | AT19: =SUM(AA19-W19)*U19-AS19 -> 6615700 | AU19: =SUM(AT19-J19) -> -103610 | AV19: =SUM(0.09*H19) -> 589500 | AW19: =SUM(AU19:AV19)/2 -> 242945 | AX19: =AW19-(AW19*10%) -> 218650.5 | AY19: 50000 | BA19: =SUM(AX19-AY19-AZ19) -> 168650.5
A20: 20 | B20: 46120 | C20: GLA | D20: 56가4320 | E20: WDCTG0JB5FJ033212 | F20: AJ | G20: con11 | H20: 8000000 | I20: 200000 | J20: =H20+I20 -> 8200000 | K20: 인천항 | L20: 완 | M20: Ramadan Xhaferi | N20: Erand derjaj | O20: J60818087L | P20: +355 692079087 | Q20: Lagja 13 , plazh Albania | R20: Albania | S20: 50%적용/ 쉬핑제외 | T20: 4750 | U20: 1713 | V20: 1465 | AA20: =SUM(T20,W20:Z20) -> 4750 | AB20: =SUM(AG20+AI20+AK20+AL20-AM20) -> 0 | AC20: =SUM(AB20-AA20) -> -4750 | AN20: 35000 | AO20: 30000 | AS20: =SUM(AN20:AR20) -> 65000 | AT20: =SUM(AA20-W20)*U20-AS20 -> 8071750 | AU20: =SUM(AT20-J20) -> -128250 | AV20: =SUM(0.09*H20) -> 720000 | AW20: =SUM(AU20:AV20)/2 -> 295875 | AX20: =AW20-(AW20*10%) -> 266287.5 | AY20: 50000 | BA20: =SUM(AX20-AY20-AZ20) -> 216287.5
A21: 21 | B21: 46121 | C21: JETTA | D21: 68주1042 | E21: WVWZZZ16ZDM078771 | F21: KCAR | G21: X | H21: 3600000 | I21: 165000 | J21: =H21+I21 -> 3765000 | K21: 인천항 | L21: 완 | M21: Ramadan Xhaferi | N21: Erand derjaj | O21: J60818087L | P21: +355 692079087 | Q21: Lagja 13 , plazh Albania | R21: Albania | S21: 50%적용/ 쉬핑제외 | T21: 2200 | U21: 1725 | V21: 1472 | AA21: =SUM(T21,W21:Z21) -> 2200 | AB21: =SUM(AG21+AI21+AK21+AL21-AM21) -> 0 | AC21: =SUM(AB21-AA21) -> -2200 | AN21: 35000 | AO21: 30000 | AS21: =SUM(AN21:AR21) -> 65000 | AT21: =SUM(AA21-W21)*U21-AS21 -> 3730000 | AU21: =SUM(AT21-J21) -> -35000 | AV21: =SUM(0.09*H21) -> 324000 | AW21: =SUM(AU21:AV21)/2 -> 144500 | AX21: =AW21-(AW21*10%) -> 130050 | AY21: 50000 | BA21: =SUM(AX21-AY21-AZ21) -> 80050
A22: 22 | B22: 46121 | C22: PASSAT | D22: 30모1529 | E22: 1VWZZZA3ZFC061301 | F22: KCAR | G22: con11 | H22: 3900000 | I22: 165000 | J22: =H22+I22 -> 4065000 | K22: 인천항 | L22: 완 | M22: Ramadan Xhaferi | N22: MYRTA NAIM | O22: G70920085G | P22: +355 692079087 | Q22: SHOERDHET | R22: Albania | S22: 50%적용/ 쉬핑제외 | T22: 2400 | U22: 1725 | V22: 1472 | AA22: =SUM(T22,W22:Z22) -> 2400 | AB22: =SUM(AG22+AI22+AK22+AL22-AM22) -> 0 | AC22: =SUM(AB22-AA22) -> -2400 | AN22: 35000 | AO22: 30000 | AS22: =SUM(AN22:AR22) -> 65000 | AT22: =SUM(AA22-W22)*U22-AS22 -> 4075000 | AU22: =SUM(AT22-J22) -> 10000 | AV22: =SUM(0.09*H22) -> 351000 | AW22: =SUM(AU22:AV22)/2 -> 180500 | AX22: =AW22-(AW22*10%) -> 162450 | AY22: 50000 | BA22: =SUM(AX22-AY22-AZ22) -> 112450
A23: 23 | B23: 46121 | C23: PASSAT | D23: 32서7449 | E23: 1VWZZZA3ZFC006849 | F23: KCAR | G23: con11 | H23: 4300000 | I23: 165000 | J23: =H23+I23 -> 4465000 | K23: 인천항 | L23: 완 | M23: Ramadan Xhaferi | N23: MYRTA NAIM | O23: G70920085G | P23: +355 692079087 | Q23: SHOERDHET | R23: Albania | S23: 50%적용/ 쉬핑제외 | T23: 2610 | U23: 1725 | V23: 1472 | AA23: =SUM(T23,W23:Z23) -> 2610 | AB23: =SUM(AG23+AI23+AK23+AL23-AM23) -> 0 | AC23: =SUM(AB23-AA23) -> -2610 | AN23: 35000 | AO23: 30000 | AS23: =SUM(AN23:AR23) -> 65000 | AT23: =SUM(AA23-W23)*U23-AS23 -> 4437250 | AU23: =SUM(AT23-J23) -> -27750 | AV23: =SUM(0.09*H23) -> 387000 | AW23: =SUM(AU23:AV23)/2 -> 179625 | AX23: =AW23-(AW23*10%) -> 161662.5 | AY23: 50000 | BA23: =SUM(AX23-AY23-AZ23) -> 111662.5
A24: 24 | B24: 46121 | C24: PEUGEOT 308 | D24: 41우0205 | E24: VF3LBBHZWGS056943 | F24: KCAR | G24: X | H24: 5000000 | I24: 165000 | J24: =H24+I24 -> 5165000 | K24: 인천항 | L24: 완 | M24: Ardian Bajram | N24: Nova auto ardi korea | O24: 1174897090 | P24: +38345883676 | Q24: Lagja Dardania , rruga Idriz Gjilani lokali Nova Bar | R24: Kosovo | S24: 완 | T24: =AA24-W24 -> 3488 | U24: 1725 | V24: 1472 | W24: 1272 | AA24: 4760 | AB24: =SUM(AG24+AI24+AK24+AL24-AM24) -> 0 | AC24: =SUM(AB24-AA24) -> -4760 | AN24: 35000 | AO24: 30000 | AS24: =SUM(AN24:AR24) -> 65000 | AT24: =SUM(AA24-W24)*U24-AS24 -> 5951800 | AU24: =SUM(AT24-J24) -> 786800 | AV24: =SUM(0.09*H24) -> 450000 | AW24: =SUM(AU24:AV24)/2 -> 618400 | AX24: =AW24-(AW24*10%) -> 556560 | AY24: 50000 | BA24: =SUM(AX24-AY24-AZ24) -> 506560
A25: 25 | B25: 46121 | C25: BMW X5 | D25: 184가6767 | E25: WBACV6100L9B07128 | G25: ="YB"&RIGHT(#REF!,6) -> #REF! | H25: 51300000 | J25: =H25+I25 -> 51300000 | K25: 인천항 | L25: 완 | M25: 888 AUTO KOSOVA | N25: BERVENIKU CORPORATION SHPK | O25: 812063709 | P25: +383 44878548 | Q25: Rruga Mon Balaj, Prishtinë, Kosovë | R25: Kosovo | S25: 입금완료 | T25: 28385 | U25: 1712 | V25: 1470 | W25: 1365 | AA25: =SUM(T25,W25:Z25) -> 29750 | AB25: =SUM(AG25+AI25+AK25+AL25-AM25) -> 0 | AC25: =SUM(AB25-AA25) -> -29750 | AD25: not paid | AN25: 35000 | AO25: 30000 | AS25: =SUM(AN25:AR25) -> 65000 | AT25: =SUM(AA25-W25)*U25-AS25 -> 48530120 | AU25: =SUM(AT25-J25) -> -2769880 | AV25: =SUM(0.09*H25) -> 4617000 | AW25: =SUM(AU25:AV25)/2 -> 923560 | AX25: =AW25-(AW25*10%) -> 831204 | AY25: 50000 | BA25: =SUM(AX25-AY25-AZ25) -> 781204
A26: 26 | B26: 46121 | C26: Q5 | D26: 53도7978 | E26: WAUZZZ8R7DA008209 | G26: 이용빈/회사 통장 50만원식 | H26: 10700000 | I26: 440000 | J26: =H26+I26 -> 11140000 | K26: 인천항 | L26: 완 | M26: Kv auto group | N26: Kolev Krasimir Hristov | O26: 6501030966 | P26: +359 89 982 0982 | Q26: Bulgaria, Varna, str. Vladislav Varnenchik 303 number 6, fl. 6 ap. 24 | R26: Bulgaria | S26: 입금완료 | T26: 6650 | U26: 1712 | V26: 1470 | X26: CON1 운항중 | AA26: =SUM(T26,W26:Z26) -> 6650 | AB26: =SUM(AG26+AI26+AK26+AL26-AM26) -> 0 | AC26: =SUM(AB26-AA26) -> -6650 | AN26: 35000 | AO26: 30000 | AS26: =SUM(AN26:AR26) -> 65000 | AT26: =SUM(AA26-W26)*U26-AS26 -> 11319800 | AU26: =SUM(AT26-J26) -> 179800 | AV26: =SUM(0.09*H26) -> 963000 | AW26: =SUM(AU26:AV26)/2 -> 571400 | AX26: =AW26-(AW26*10%) -> 514260 | AY26: 50000 | BA26: =SUM(AX26-AY26-AZ26) -> 464260
A27: 27 | B27: 46121 | C27: Benz GLE 300 D 4 MATIC | D27: 298저1919 | E27: WDCFB1KB8KA076789 | F27: 정모터스/ 정상근 | G27: 이용빈 계약 50만 | H27: 44000000 | J27: =H27+I27 -> 44000000 | K27: 인천항 | L27: 완 | M27: Idealshped | N27: Sasa Vulovic B.l. | O27: 810209868 | P27: +383 49 822 255 | Q27: Donje Varage zubin Potok | R27: Kosovo | S27: 입금완료 | T27: 23833 | U27: 1722 | V27: 1495 | W27: 1467 | AA27: =SUM(T27,W27:Z27) -> 25300 | AB27: =SUM(AG27+AI27+AK27+AL27-AM27) -> 0 | AC27: =SUM(AB27-AA27) -> -25300 | AN27: 35000 | AO27: 30000 | AS27: =SUM(AN27:AR27) -> 65000 | AT27: =SUM(AA27-W27)*U27-AS27 -> 40975426 | AU27: =SUM(AT27-J27) -> -3024574 | AV27: =SUM(0.09*H27) -> 3960000 | AW27: =SUM(AU27:AV27)/2 -> 467713 | AX27: =AW27-(AW27*10%) -> 420941.7 | AY27: 50000 | BA27: =SUM(AX27-AY27-AZ27) -> 370941.7
A28: 28 | B28: 46121 | C28: Arteon | D28: 253머1590 | E28: WVWZZZ3HZKE012994 | F28: 레인보우 | G28: 이용빈/회사 통장 50만원식 | H28: 18100000 | I28: 440000 | J28: =H28+I28 -> 18540000 | K28: 인천항 | L28: 완 | M28: Kv auto group | N28: Svetoslav Ivanov Ivanov | O28: 9702098726 | P28: +359 89 982 0982 | Q28: Plovdiv , Str. Asen Hristoforov №25 | R28: Bulgaria | S28: 입금완료 | T28: 11000 | U28: 1712 | V28: 1470 | X28: CON1 운항중 | AA28: =SUM(T28,W28:Z28) -> 11000 | AB28: =SUM(AG28+AI28+AK28+AL28-AM28) -> 0 | AC28: =SUM(AB28-AA28) -> -11000 | AN28: 35000 | AO28: 30000 | AS28: =SUM(AN28:AR28) -> 65000 | AT28: =SUM(AA28-W28)*U28-AS28 -> 18767000 | AU28: =SUM(AT28-J28) -> 227000 | AV28: =SUM(0.09*H28) -> 1629000 | AW28: =SUM(AU28:AV28)/2 -> 928000 | AX28: =AW28-(AW28*10%) -> 835200 | AY28: 50000 | BA28: =SUM(AX28-AY28-AZ28) -> 785200
A29: 29 | B29: 46121 | C29: Niro | D29: 06마5650 | E29: KNACB81CGJA175189 | F29: 뉴코리아코터스 | G29: 이용빈 통장 100만원 | H29: 10700000 | I29: 440000 | J29: =H29+I29 -> 11140000 | K29: 인천항 | L29: 완 | M29: AUTO SHQIPONZA | N29: BUZANI REXHEP | O29: K10703071M | P29: +0696591358 | Q29: DURRES POST | R29: Albania | S29: 26.04.11 | T29: 6220 | U29: 1712 | V29: 1470 | W29: 1280 | AA29: =SUM(T29,W29:Z29) -> 7500 | AB29: 8100 | AC29: =SUM(AB29-AA29) -> 600 | AD29: 8100입금 | AE29: 600 선수금 | AN29: 35000 | AO29: 30000 | AS29: =SUM(AN29:AR29) -> 65000 | AT29: =SUM(AA29-W29)*U29-AS29 -> 10583640 | AU29: =SUM(AT29-J29) -> -556360 | AV29: =SUM(0.09*H29) -> 963000 | AW29: =SUM(AU29:AV29)/2 -> 203320 | AX29: =AW29-(AW29*10%) -> 182988 | AY29: 50000 | BA29: =SUM(AX29-AY29-AZ29) -> 132988
A30: 30 | B30: 46127 | C30: A6 | D30: 103러8412 | E30: WAUZZZ4G0GN159300 | F30: 위즈모토모티브 | G30: 이용빈 계약 50만 | H30: =13500000-I29 -> 13060000 | I30: 440000 | J30: =H30+I30 -> 13500000 | K30: 인천항 | L30: 완 | M30: FER-GROUP SH.P.K | N30: FERGROUP SHPK | O30: 811054999 | P30: ‪+383 48 238888‪ | Q30: DURRES POST | R30: Kosovo | S30: 2026.04.30 | T30: =9000-W30 -> 7733 | U30: 1723 | V30: 1465 | W30: 1267 | AA30: =SUM(T30,W30:Z30) -> 9000 | AB30: =SUM(AG30+AI30+AK30+AL30-AM30) -> 0 | AC30: =SUM(AB30-AA30) -> -9000 | AN30: 35000 | AO30: 30000 | AS30: =SUM(AN30:AR30) -> 65000 | AT30: =SUM(AA30-W30)*U30-AS30 -> 13258959 | AU30: =SUM(AT30-J30) -> -241041 | AV30: =SUM(0.09*H30) -> 1175400 | AW30: =SUM(AU30:AV30)/2 -> 467179.5 | AX30: =AW30-(AW30*10%) -> 420461.55 | AY30: 50000 | BA30: =SUM(AX30-AY30-AZ30) -> 370461.55
A31: 31 | B31: 46127 | C31: C220 d | D31: 383더9665 | E31: WDDWF0EBXFF087307 | F31: 강남모터스 | G31: 이용빈 통장 100만원 | H31: =12700000-I31 -> 12260000 | I31: 440000 | J31: =H31+I31 -> 12700000 | K31: 인천항 | L31: 완 | M31: AUTO SHQIPONZA | N31: Zheleku Aleks | O31: J80222017M | P31: +0696591358 | Q31: DURRES POST | R31: Albania | S31: 미수 | T31: 7733 | U31: 1723 | V31: 1465 | W31: 1267 | AA31: =SUM(T31,W31:Z31) -> 9000 | AB31: =SUM(AG31+AI31+AK31+AL31-AM31) -> 0 | AN31: 35000 | AO31: 30000 | AS31: =SUM(AN31:AR31) -> 65000 | AT31: =SUM(AA31-W31)*U31-AS31 -> 13258959 | AU31: =SUM(AT31-J31) -> 558959 | AV31: =SUM(0.09*H31) -> 1103400 | AW31: =SUM(AU31:AV31)/2 -> 831179.5 | AX31: =AW31-(AW31*10%) -> 748061.55 | AY31: 50000 | BA31: =SUM(AX31-AY31-AZ31) -> 698061.55
A32: 32 | B32: 46127 | C32: VolvoXC40T4 | D32: 366머7245 | E32: YV1XZACACL2259209 | F32: 에키원모터스 | G32: 이용빈 계약 50만 | H32: =18000000-I31 -> 17560000 | I32: 440000 | J32: =H32+I32 -> 18000000 | K32: 인천항 | L32: 완 | M32: 888 AUTO KOSOVA | N32: Marjan Spasic | O32: 1232286519 | P32: +383 44878548 | Q32: Selo Gotovusa, Strpce | R32: Kosovo | S32: 입금예정. | T32: =11450-W32 -> 10098 | U32: 1723 | V32: 1465 | W32: 1352 | AA32: =SUM(T32,W32:Z32) -> 11450 | AB32: =SUM(AG32+AI32+AK32+AL32-AM32) -> 0 | AD32: not paid | AN32: 35000 | AO32: 30000 | AS32: =SUM(AN32:AR32) -> 65000 | AT32: =SUM(AA32-W32)*U32-AS32 -> 17333854 | AU32: =SUM(AT32-J32) -> -666146 | AV32: =SUM(0.09*H32) -> 1580400 | AW32: =SUM(AU32:AV32)/2 -> 457127 | AX32: =AW32-(AW32*10%) -> 411414.3 | AY32: 50000 | BA32: =SUM(AX32-AY32-AZ32) -> 361414.3
A33: 33 | B33: 46127 | C33: GOLF | D33: 28고8915 | E33: WVWZZZAUZFW123794 | F33: AJ | G33: con11 | H33: 6100000 | I33: 165000 | J33: =H33+I33 -> 6265000 | K33: 인천항 | L33: 완 | M33: Ramadan Xhaferi | N33: Erand derjaj | O33: J60818087L | P33: +355 692079087 | Q33: Lagja 13 , plazh Albania | R33: Albania | S33: 50%적용/ 쉬핑제외 | T33: 3600 | U33: 1723 | V33: 1465 | AA33: =SUM(T33,W33:Z33) -> 3600 | AB33: =SUM(AG33+AI33+AK33+AL33-AM33) -> 0 | AN33: 35000 | AO33: 30000 | AS33: =SUM(AN33:AR33) -> 65000 | AT33: =SUM(AA33-W33)*U33-AS33 -> 6137800 | AU33: =SUM(AT33-J33) -> -127200 | AV33: =SUM(0.09*H33) -> 549000 | AW33: =SUM(AU33:AV33)/2 -> 210900 | AX33: =AW33-(AW33*10%) -> 189810 | AY33: 50000 | BA33: =SUM(AX33-AY33-AZ33) -> 139810
A34: 34 | B34: 46131 | C34: A6 | D34: 124모8906 | E34: WAUZZZF29LN064990 | F34: ㈜에스원모터스 | G34: 이용빈 계약 100만 | H34: 26000000 | I34: 440000 | J34: =H34+I34 -> 26440000 | K34: 인천항 | L34: 완 | M34: 888 AUTO KOSOVA | N34: Shkurte Rrahmani Duriqi | O34: 12311427734 | P34: +38344851128 | Q34: Rr. Jakup Ferri - Prishtine | R34: Kosovo | S34: 입금완료/300유로손상보상 | T34: =16100-W34 -> 14833 | U34: 1711 | V34: 1455 | W34: 1267 | AA34: 16100 | AB34: =SUM(AG34+AI34+AK34+AL34-AM34) -> 0 | AD34: not paid | AN34: 35000 | AO34: 30000 | AS34: =SUM(AN34:AR34) -> 65000 | AT34: =SUM(AA34-W34)*U34-AS34 -> 25314263 | AU34: =SUM(AT34-J34) -> -1125737 | AV34: =SUM(0.09*H34) -> 2340000 | AW34: =SUM(AU34:AV34)/2 -> 607131.5 | AX34: =AW34-(AW34*10%) -> 546418.35 | AY34: 50000 | BA34: =SUM(AX34-AY34-AZ34) -> 496418.35
A35: 35 | B35: 46129 | C35: TIGUAN | D35: 27서7560 | E35: WVGZZZ5NZFW500635 | F35: ㈜제이씨오토 | G35: 이용빈 계약 50만 | H35: =8300000-I35 -> 7860000 | I35: 440000 | J35: =H35+I35 -> 8300000 | K35: 인천항 | L35: 완 | M35: AUTO SHQIPONZA | N35: Bicaku Elda | O35: K35923063B | P35: +0696591358 | Q35: DURRES POST | R35: Albania | S35: 6550. 26.04.21 | T35: 2850 | U35: 1711 | V35: 1455 | W35: 1350 | AA35: =SUM(T35,W35:Z35) -> 4200 | AB35: =SUM(AG35+AI35+AK35+AL35-AM35) -> 0 | AC35: =6550-6050 -> 500 | AD35: 6550 | AE35: 500 선수금 | AN35: 35000 | AO35: 30000 | AS35: =SUM(AN35:AR35) -> 65000 | AT35: =SUM(AA35-W35)*U35-AS35 -> 4811350 | AU35: =SUM(AT35-J35) -> -3488650 | AV35: =SUM(0.09*H35) -> 707400 | AW35: =SUM(AU35:AV35)/2 -> -1390625 | AX35: =AW35-(AW35*10%) -> -1251562.5 | AY35: 50000 | BA35: =SUM(AX35-AY35-AZ35) -> -1301562.5
A36: 36 | B36: 46121 | C36: I30 | D36: 11오9354 | E36: KMHD251UBCU011162 | F36: KCAR | G36: con10 | H36: 3050000 | I36: 165000 | J36: =H36+I36 -> 3215000 | K36: 인천항 | L36: 완 | M36: Ramadan Xhaferi | N36: Fetishi Evisa | O36: I85526073O | P36: +355 692079087 | Q36: Tirane, Albania | R36: Albania | S36: 50%적용/ 쉬핑제외 | T36: 2000 | U36: 1725 | V36: 1472 | AA36: =SUM(T36,W36:Z36) -> 2000 | AB36: =SUM(AG36+AI36+AK36+AL36-AM36) -> 0 | AN36: 35000 | AO36: 30000 | AS36: =SUM(AN36:AR36) -> 65000 | AT36: =SUM(AA36-W36)*U36-AS36 -> 3385000 | AU36: =SUM(AT36-J36) -> 170000 | AV36: =SUM(0.09*H36) -> 274500 | AW36: =SUM(AU36:AV36)/2 -> 222250 | AX36: =AW36-(AW36*10%) -> 200025 | AY36: 50000 | BA36: =SUM(AX36-AY36-AZ36) -> 150025
